Workbook

Sheet 2025年4月 
A1: 45748 | C1: １年 | E1: ２年 | G1: ３年 | I1: ４年 | K1: 助産 | M1: 研究課程部 Ｍ１ | O1: 研究課程部 Ｍ２ | Q1: 研究課程部 Ｄ１ | S1: 研究課程部 Ｄ２３ | U1: =A1 -> 45748 | V1: 授業外その他教室等管理スケジュール | AA1: １階 | AG1: ２階 | AW1: ３階 | BI1: ４階 | BK1: 体育棟 | BM1: 研修棟
C2: =A1 -> 45748 | U2: =C2 -> 45748 | AA2: 101 | AB2: 102 | AC2: 103 | AD2: 在宅実習室 | AE2: 成人実習室 | AF2: 講堂 | AG2: 201 | AH2: 202 | AI2: 203 | AJ2: 204 | AK2: 205 | AL2: 基礎実習室 | AM2: 母性小児実習室 | AN2: 演習21 | AO2: 演習22 | AP2: 演習23 | AQ2: 演習24 | AR2: 演習25 | AS2: 演習26 | AT2: 演習27 | AU2: 演習28 | AV2: 演習29 | AW2: 301 | AX2: 302 | AY2: 303 | AZ2: 304 | BA2: 臨床１ | BB2: 臨床２ | BC2: LL1 | BD2: LL2 | BE2: 実験室 | BF2: 情報処理室 | BG2: 演習31 | BH2: 演習32 | BI2: セミナー室１ | BJ2: セミナー室２ | BK2: 大講義室 | BL2: アリーナ | BM2: 研修１ | BN2: 研修３ | BO2: 研修４ | BP2: 研修５ | BQ2: 研修６ | BR2: 研修７ | BS2: 視聴覚室
A3: １時限（09：20～10：50） | B3: 科目名 | C3: =VLOOKUP($C2,'2025年度(1年前期)'!$B$5:$N$208,COLUMN('2025年度(1年前期)'!$C$5),0)&"" | E3: =VLOOKUP($C2,'2025年度(2年前期)'!$B$5:$N$208,COLUMN('2025年度(2年前期)'!$C$5),0)&"" | G3: =VLOOKUP($C2,'2025年度(3年前期)'!$B$5:$N$208,COLUMN('2025年度(3年前期)'!$C$5),0)&"" | I3: =VLOOKUP($C2,'2025年度(4年前期)'!$B$5:$N$208,COLUMN('2025年度(4年前期)'!$C$5),0)&"" | K3: =VLOOKUP($C2,'2025年度(助産前期)'!$B$5:$N$208,COLUMN('2025年度(助産前期)'!$C$5),0)&"" | M3: =VLOOKUP($C2,'2025年度(M1前期)'!$B$5:$N$208,COLUMN('2025年度(M1前期)'!$C$5),0)&"" | O3: =VLOOKUP($C2,'2025年度(M2前期)'!$B$5:$N$208,COLUMN('2025年度(M2前期)'!$C$5),0)&"" | Q3: =VLOOKUP($C2,'2025年度(D1前期)'!$B$5:$N$208,COLUMN('2025年度(D1前期)'!$C$5),0)&"" | S3: =VLOOKUP($C2,'2025年度(D23前期)'!$B$5:$N$208,COLUMN('2025年度(D23前期)'!$C$5),0)&"" | U3: 1～2限、4限 | Z3: =A3 -> １時限（09：20～10：50） | AK3: NCGM面接練習
B4: 教 官 | C4: =IFERROR(VLOOKUP(C3,科目・教員!$A$1:$B$357,2,0),"") | E4: =IFERROR(VLOOKUP(E3,科目・教員!$A$1:$B$357,2,0),"") | G4: =IFERROR(VLOOKUP(G3,科目・教員!$A$1:$B$357,2,0),"") | I4: =IFERROR(VLOOKUP(I3,科目・教員!$A$1:$B$357,2,0),"") | K4: =IFERROR(VLOOKUP(K3,科目・教員!$A$1:$B$357,2,0),"") | M4: =IFERROR(VLOOKUP(M3,科目・教員!$A$1:$B$357,2,0),"") | O4: =IFERROR(VLOOKUP(O3,科目・教員!$A$1:$B$357,2,0),"") | Q4: =IFERROR(VLOOKUP(Q3,科目・教員!$A$1:$B$357,2,0),"") | S4: =IFERROR(VLOOKUP(S3,科目・教員!$A$1:$B$357,2,0),"") | U4: NCGM面接練習
B5: 使用教室 | C5: =VLOOKUP($C2,'2025年度(1年前期)'!$B$5:$N$208,COLUMN('2025年度(1年前期)'!$C$5)+1,0)&"" | E5: =VLOOKUP($C2,'2025年度(2年前期)'!$B$5:$N$208,COLUMN('2025年度(2年前期)'!$C$5)+1,0)&"" | G5: =VLOOKUP($C2,'2025年度(3年前期)'!$B$5:$N$208,COLUMN('2025年度(3年前期)'!$C$5)+1,0)&"" | I5: =VLOOKUP($C2,'2025年度(4年前期)'!$B$5:$N$208,COLUMN('2025年度(4年前期)'!$C$5)+1,0)&"" | K5: =VLOOKUP($C2,'2025年度(助産前期)'!$B$5:$N$208,COLUMN('2025年度(助産前期)'!$C$5)+1,0)&"" | M5: =VLOOKUP($C2,'2025年度(M1前期)'!$B$5:$N$208,COLUMN('2025年度(M1前期)'!C$5)+1,0)&"" | O5: =VLOOKUP($C2,'2025年度(M2前期)'!$B$5:$N$208,COLUMN('2025年度(M2前期)'!$C$5)+1,0)&"" | Q5: =VLOOKUP($C2,'2025年度(D1前期)'!$B$5:$N$208,COLUMN('2025年度(D1前期)'!$C$5)+1,0)&"" | S5: =VLOOKUP($C2,'2025年度(D23前期)'!$B$5:$N$208,COLUMN('2025年度(D23前期)'!$C$5)+1,0)&"" | U5: 205教室
B6: 備 考 | U6: 髙木先生
A7: ２時限（11：00～12：30） | B7: 科目名 | C7: =VLOOKUP($C2,'2025年度(1年前期)'!$B$5:$N$208,COLUMN('2025年度(1年前期)'!$E$5),0)&"" | E7: =VLOOKUP($C2,'2025年度(2年前期)'!$B$5:$N$208,COLUMN('2025年度(2年前期)'!$E$5),0)&"" | G7: =VLOOKUP($C2,'2025年度(3年前期)'!$B$5:$N$208,COLUMN('2025年度(3年前期)'!$E$5),0)&"" | I7: =VLOOKUP($C2,'2025年度(4年前期)'!$B$5:$N$208,COLUMN('2025年度(4年前期)'!$E$5),0)&"" | K7: =VLOOKUP($C2,'2025年度(助産前期)'!$B$5:$N$208,COLUMN('2025年度(助産前期)'!$E$5),0)&"" | M7: =VLOOKUP($C2,'2025年度(M1前期)'!$B$5:$N$208,COLUMN('2025年度(M1前期)'!$E$5),0)&"" | O7: =VLOOKUP($C2,'2025年度(M2前期)'!$B$5:$N$208,COLUMN('2025年度(M2前期)'!$E$5),0)&"" | Q7: =VLOOKUP($C2,'2025年度(D1前期)'!$B$5:$N$208,COLUMN('2025年度(D1前期)'!$E$5),0)&"" | S7: =VLOOKUP($C2,'2025年度(D23前期)'!$B$5:$N$208,COLUMN('2025年度(D23前期)'!$E$5),0)&"" | Z7: =A7 -> ２時限（11：00～12：30） | AK7: NCGM面接練習
B8: 教 官 | C8: =IFERROR(VLOOKUP(C7,科目・教員!$A$1:$B$357,2,0),"") | E8: =IFERROR(VLOOKUP(E7,科目・教員!$A$1:$B$357,2,0),"") | G8: =IFERROR(VLOOKUP(G7,科目・教員!$A$1:$B$357,2,0),"") | I8: =IFERROR(VLOOKUP(I7,科目・教員!$A$1:$B$357,2,0),"") | K8: =IFERROR(VLOOKUP(K7,科目・教員!$A$1:$B$357,2,0),"") | M8: =IFERROR(VLOOKUP(M7,科目・教員!$A$1:$B$357,2,0),"") | O8: =IFERROR(VLOOKUP(O7,科目・教員!$A$1:$B$357,2,0),"") | Q8: =IFERROR(VLOOKUP(Q7,科目・教員!$A$1:$B$357,2,0),"") | S8: =IFERROR(VLOOKUP(S7,科目・教員!$A$1:$B$357,2,0),"")
B9: 使用教室 | C9: =VLOOKUP($C2,'2025年度(1年前期)'!$B$5:$N$208,COLUMN('2025年度(1年前期)'!$E$5)+1,0)&"" | E9: =VLOOKUP($C2,'2025年度(2年前期)'!$B$5:$N$208,COLUMN('2025年度(2年前期)'!$E$5)+1,0)&"" | G9: =VLOOKUP($C2,'2025年度(3年前期)'!$B$5:$N$208,COLUMN('2025年度(3年前期)'!$E$5)+1,0)&"" | I9: =VLOOKUP($C2,'2025年度(4年前期)'!$B$5:$N$208,COLUMN('2025年度(4年前期)'!$E$5)+1,0)&"" | K9: =VLOOKUP($C2,'2025年度(助産前期)'!$B$5:$N$208,COLUMN('2025年度(助産前期)'!$E$5)+1,0)&"" | M9: =VLOOKUP($C2,'2025年度(M1前期)'!$B$5:$N$208,COLUMN('2025年度(M1前期)'!$E$5)+1,0)&"" | O9: =VLOOKUP($C2,'2025年度(M2前期)'!$B$5:$N$208,COLUMN('2025年度(M2前期)'!$E$5)+1,0)&"" | Q9: =VLOOKUP($C2,'2025年度(D1前期)'!$B$5:$N$208,COLUMN('2025年度(D1前期)'!$E$5)+1,0)&"" | S9: =VLOOKUP($C2,'2025年度(D23前期)'!$B$5:$N$208,COLUMN('2025年度(D23前期)'!$E$5)+1,0)&""
B10: 備 考
A11: 昼休み（12：30～13：30） | B11: 活動名 | Z11: =A11 -> 昼休み（12：30～13：30）
B12: 責任者
B13: 使用教室
B14: 備 考 | U14: 共同研究室1・7
A15: ３時限（13：30～15：00） | B15: 科目名 | C15: =VLOOKUP($C2,'2025年度(1年前期)'!$B$5:$N$208,COLUMN('2025年度(1年前期)'!$G$5),0)&"" | E15: =VLOOKUP($C2,'2025年度(2年前期)'!$B$5:$N$208,COLUMN('2025年度(2年前期)'!$G$5),0)&"" | G15: =VLOOKUP($C2,'2025年度(3年前期)'!$B$5:$N$208,COLUMN('2025年度(3年前期)'!$G$5),0)&"" | I15: =VLOOKUP($C2,'2025年度(4年前期)'!$B$5:$N$208,COLUMN('2025年度(4年前期)'!$G$5),0)&"" | K15: =VLOOKUP($C2,'2025年度(助産前期)'!$B$5:$N$208,COLUMN('2025年度(助産前期)'!$G$5),0)&"" | M15: =VLOOKUP($C2,'2025年度(M1前期)'!$B$5:$N$208,COLUMN('2025年度(M1前期)'!$G$5),0)&"" | O15: =VLOOKUP($C2,'2025年度(M2前期)'!$B$5:$N$208,COLUMN('2025年度(M2前期)'!$G$5),0)&"" | Q15: =VLOOKUP($C2,'2025年度(D1前期)'!$B$5:$N$208,COLUMN('2025年度(D1前期)'!$G$5),0)&"" | S15: =VLOOKUP($C2,'2025年度(D23前期)'!$B$5:$N$208,COLUMN('2025年度(D23前期)'!$G$5),0)&"" | U15: 13時～15時 | Z15: =A15 -> ３時限（13：30～15：00）
B16: 教 官 | C16: =IFERROR(VLOOKUP(C15,科目・教員!$A$1:$B$357,2,0),"") | E16: =IFERROR(VLOOKUP(E15,科目・教員!$A$1:$B$357,2,0),"") | G16: =IFERROR(VLOOKUP(G15,科目・教員!$A$1:$B$357,2,0),"") | I16: =IFERROR(VLOOKUP(I15,科目・教員!$A$1:$B$357,2,0),"") | K16: =IFERROR(VLOOKUP(K15,科目・教員!$A$1:$B$357,2,0),"") | M16: =IFERROR(VLOOKUP(M15,科目・教員!$A$1:$B$357,2,0),"") | O16: =IFERROR(VLOOKUP(O15,科目・教員!$A$1:$B$357,2,0),"") | Q16: =IFERROR(VLOOKUP(Q15,科目・教員!$A$1:$B$357,2,0),"") | S16: =IFERROR(VLOOKUP(S15,科目・教員!$A$1:$B$357,2,0),"") | U16: 山下
B17: 使用教室 | C17: =VLOOKUP($C2,'2025年度(1年前期)'!$B$5:$N$208,COLUMN('2025年度(1年前期)'!$G$5)+1,0)&"" | E17: =VLOOKUP($C2,'2025年度(2年前期)'!$B$5:$N$208,COLUMN('2025年度(2年前期)'!$G$5)+1,0)&"" | G17: =VLOOKUP($C2,'2025年度(3年前期)'!$B$5:$N$208,COLUMN('2025年度(3年前期)'!$G$5)+1,0)&"" | I17: =VLOOKUP($C2,'2025年度(4年前期)'!$B$5:$N$208,COLUMN('2025年度(4年前期)'!$G$5)+1,0)&"" | K17: =VLOOKUP($C2,'2025年度(助産前期)'!$B$5:$N$208,COLUMN('2025年度(助産前期)'!$G$5)+1,0)&"" | M17: =VLOOKUP($C2,'2025年度(M1前期)'!$B$5:$N$208,COLUMN('2025年度(M1前期)'!$G$5)+1,0)&"" | O17: =VLOOKUP($C2,'2025年度(M2前期)'!$B$5:$N$208,COLUMN('2025年度(M2前期)'!$G$5)+1,0)&"" | Q17: =VLOOKUP($C2,'2025年度(D1前期)'!$B$5:$N$208,COLUMN('2025年度(D1前期)'!$G$5)+1,0)&"" | S17: =VLOOKUP($C2,'2025年度(D23前期)'!$B$5:$N$208,COLUMN('2025年度(D23前期)'!$G$5)+1,0)&""
B18: 備 考
A19: ４時限（15：10～16：40） | B19: 科目名 | C19: =VLOOKUP($C2,'2025年度(1年前期)'!$B$5:$N$208,COLUMN('2025年度(1年前期)'!$I$5),0)&"" | E19: =VLOOKUP($C2,'2025年度(2年前期)'!$B$5:$N$208,COLUMN('2025年度(2年前期)'!$I$5),0)&"" | G19: =VLOOKUP($C2,'2025年度(3年前期)'!$B$5:$N$208,COLUMN('2025年度(3年前期)'!$I$5),0)&"" | I19: =VLOOKUP($C2,'2025年度(4年前期)'!$B$5:$N$208,COLUMN('2025年度(4年前期)'!$I$5),0)&"" | K19: =VLOOKUP($C2,'2025年度(助産前期)'!$B$5:$N$208,COLUMN('2025年度(助産前期)'!$I$5),0)&"" | M19: =VLOOKUP($C2,'2025年度(M1前期)'!$B$5:$N$208,COLUMN('2025年度(M1前期)'!$I$5),0)&"" | O19: =VLOOKUP($C2,'2025年度(M2前期)'!$B$5:$N$208,COLUMN('2025年度(M2前期)'!$I$5),0)&"" | Q19: =VLOOKUP($C2,'2025年度(D1前期)'!$B$5:$N$208,COLUMN('2025年度(D1前期)'!$I$5),0)&"" | S19: =VLOOKUP($C2,'2025年度(D23前期)'!$B$5:$N$208,COLUMN('2025年度(D23前期)'!$I$5),0)&"" | Z19: =A19 -> ４時限（15：10～16：40） | AK19: NCGM面接練習
B20: 教 官 | C20: =IFERROR(VLOOKUP(C19,科目・教員!$A$1:$B$357,2,0),"") | E20: =IFERROR(VLOOKUP(E19,科目・教員!$A$1:$B$357,2,0),"") | G20: =IFERROR(VLOOKUP(G19,科目・教員!$A$1:$B$357,2,0),"") | I20: =IFERROR(VLOOKUP(I19,科目・教員!$A$1:$B$357,2,0),"") | K20: =IFERROR(VLOOKUP(K19,科目・教員!$A$1:$B$357,2,0),"") | M20: =IFERROR(VLOOKUP(M19,科目・教員!$A$1:$B$357,2,0),"") | O20: =IFERROR(VLOOKUP(O19,科目・教員!$A$1:$B$357,2,0),"") | Q20: =IFERROR(VLOOKUP(Q19,科目・教員!$A$1:$B$357,2,0),"") | S20: =IFERROR(VLOOKUP(S19,科目・教員!$A$1:$B$357,2,0),"")
B21: 使用教室 | C21: =VLOOKUP($C2,'2025年度(1年前期)'!$B$5:$N$208,COLUMN('2025年度(1年前期)'!$I$5)+1,0)&"" | E21: =VLOOKUP($C2,'2025年度(2年前期)'!$B$5:$N$208,COLUMN('2025年度(2年前期)'!$I$5)+1,0)&"" | G21: =VLOOKUP($C2,'2025年度(3年前期)'!$B$5:$N$208,COLUMN('2025年度(3年前期)'!$I$5)+1,0)&"" | I21: =VLOOKUP($C2,'2025年度(4年前期)'!$B$5:$N$208,COLUMN('2025年度(4年前期)'!$I$5)+1,0)&"" | K21: =VLOOKUP($C2,'2025年度(助産前期)'!$B$5:$N$208,COLUMN('2025年度(助産前期)'!$I$5)+1,0)&"" | M21: =VLOOKUP($C2,'2025年度(M1前期)'!$B$5:$N$208,COLUMN('2025年度(M1前期)'!$I$5)+1,0)&"" | O21: =VLOOKUP($C2,'2025年度(M2前期)'!$B$5:$N$208,COLUMN('2025年度(M2前期)'!$I$5)+1,0)&"" | Q21: =VLOOKUP($C2,'2025年度(D1前期)'!$B$5:$N$208,COLUMN('2025年度(D1前期)'!$I$5)+1,0)&"" | S21: =VLOOKUP($C2,'2025年度(D23前期)'!$B$5:$N$208,COLUMN('2025年度(D23前期)'!$I$5)+1,0)&""
B22: 備 考
A23: ５時限（16：50～18：20） | B23: 科目名 | C23: =VLOOKUP($C2,'2025年度(1年前期)'!$B$5:$N$208,COLUMN('2025年度(1年前期)'!$K$5),0)&"" | E23: =VLOOKUP($C2,'2025年度(2年前期)'!$B$5:$N$208,COLUMN('2025年度(2年前期)'!$K$5),0)&"" | G23: =VLOOKUP($C2,'2025年度(3年前期)'!$B$5:$N$208,COLUMN('2025年度(3年前期)'!$K$5),0)&"" | I23: =VLOOKUP($C2,'2025年度(4年前期)'!$B$5:$N$208,COLUMN('2025年度(4年前期)'!$K$5),0)&"" | K23: =VLOOKUP($C2,'2025年度(助産前期)'!$B$5:$N$208,COLUMN('2025年度(助産前期)'!$K$5),0)&"" | M23: =VLOOKUP($C2,'2025年度(M1前期)'!$B$5:$N$208,COLUMN('2025年度(M1前期)'!$K$5),0)&"" | O23: =VLOOKUP($C2,'2025年度(M2前期)'!$B$5:$N$208,COLUMN('2025年度(M2前期)'!$K$5),0)&"" | Q23: =VLOOKUP($C2,'2025年度(D1前期)'!$B$5:$N$208,COLUMN('2025年度(D1前期)'!$K$5),0)&"" | S23: =VLOOKUP($C2,'2025年度(D23前期)'!$B$5:$N$208,COLUMN('2025年度(D23前期)'!$K$5),0)&"" | Z23: =A23 -> ５時限（16：50～18：20）
B24: 教 官 | C24: =IFERROR(VLOOKUP(C23,科目・教員!$A$1:$B$357,2,0),"") | E24: =IFERROR(VLOOKUP(E23,科目・教員!$A$1:$B$357,2,0),"") | G24: =IFERROR(VLOOKUP(G23,科目・教員!$A$1:$B$357,2,0),"") | I24: =IFERROR(VLOOKUP(I23,科目・教員!$A$1:$B$357,2,0),"") | K24: =IFERROR(VLOOKUP(K23,科目・教員!$A$1:$B$357,2,0),"") | M24: =IFERROR(VLOOKUP(M23,科目・教員!$A$1:$B$357,2,0),"") | O24: =IFERROR(VLOOKUP(O23,科目・教員!$A$1:$B$357,2,0),"") | Q24: =IFERROR(VLOOKUP(Q23,科目・教員!$A$1:$B$357,2,0),"") | S24: =IFERROR(VLOOKUP(S23,科目・教員!$A$1:$B$357,2,0),"")
B25: 使用教室 | C25: =VLOOKUP($C2,'2025年度(1年前期)'!$B$5:$N$208,COLUMN('2025年度(1年前期)'!$K$5)+1,0)&"" | E25: =VLOOKUP($C2,'2025年度(2年前期)'!$B$5:$N$208,COLUMN('2025年度(2年前期)'!$K$5)+1,0)&"" | G25: =VLOOKUP($C2,'2025年度(3年前期)'!$B$5:$N$208,COLUMN('2025年度(3年前期)'!$K$5)+1,0)&"" | I25: =VLOOKUP($C2,'2025年度(4年前期)'!$B$5:$N$208,COLUMN('2025年度(4年前期)'!$K$5)+1,0)&"" | K25: =VLOOKUP($C2,'2025年度(助産前期)'!$B$5:$N$208,COLUMN('2025年度(助産前期)'!$K$5)+1,0)&"" | M25: =VLOOKUP($C2,'2025年度(M1前期)'!$B$5:$N$208,COLUMN('2025年度(M1前期)'!$K$5)+1,0)&"" | O25: =VLOOKUP($C2,'2025年度(M2前期)'!$B$5:$N$208,COLUMN('2025年度(M2前期)'!$K$5)+1,0)&"" | Q25: =VLOOKUP($C2,'2025年度(D1前期)'!$B$5:$N$208,COLUMN('2025年度(D1前期)'!$K$5)+1,0)&"" | S25: =VLOOKUP($C2,'2025年度(D23前期)'!$B$5:$N$208,COLUMN('2025年度(D23前期)'!$K$5)+1,0)&""
B26: 備 考
C27: =C2+1 -> 45749 | U27: =C27 -> 45749 | AA27: 101 | AB27: 102 | AC27: 103 | AD27: 在宅実習室 | AE27: 成人実習室 | AF27: 講堂 | AG27: 201 | AH27: 202 | AI27: 203 | AJ27: 204 | AK27: 205 | AL27: 基礎実習室 | AM27: 母性・小児実習室 | AN27: 演習21 | AO27: 演習22 | AP27: 演習23 | AQ27: 演習24 | AR27: 演習25 | AS27: 演習26 | AT27: 演習27 | AU27: 演習28 | AV27: 演習29 | AW27: 301 | AX27: 302 | AY27: 303 | AZ27: 304 | BA27: 臨床１ | BB27: 臨床２ | BC27: LL1 | BD27: LL2 | BE27: 実験室 | BF27: 情報処理室 | BG27: 演習31 | BH27: 演習32 | BI27: セミナー室１ | BJ27: セミナー室２ | BK27: 大講義室 | BL27: アリーナ | BM27: 研修１ | BN27: 研修３ | BO27: 研修４ | BP27: 研修５ | BQ27: 研修６ | BR27: 研修７ | BS27: 視聴覚室
A28: １時限（09：20～10：50） | B28: 科目名 | C28: =VLOOKUP($C27,'2025年度(1年前期)'!$B$5:$N$208,COLUMN('2025年度(1年前期)'!$C$5),0)&"" | E28: =VLOOKUP($C27,'2025年度(2年前期)'!$B$5:$N$208,COLUMN('2025年度(2年前期)'!$C$5),0)&"" | G28: =VLOOKUP($C27,'2025年度(3年前期)'!$B$5:$N$208,COLUMN('2025年度(3年前期)'!$C$5),0)&"" -> 必修科目教科書販売 | I28: =VLOOKUP($C27,'2025年度(4年前期)'!$B$5:$N$208,COLUMN('2025年度(4年前期)'!$C$5),0)&"" -> 必修科目教科書販売 | K28: =VLOOKUP($C27,'2025年度(助産前期)'!$B$5:$N$208,COLUMN('2025年度(助産前期)'!$C$5),0)&"" | M28: =VLOOKUP($C27,'2025年度(M1前期)'!$B$5:$N$208,COLUMN('2025年度(M1前期)'!$C$5),0)&"" | O28: =VLOOKUP($C27,'2025年度(M2前期)'!$B$5:$N$208,COLUMN('2025年度(M2前期)'!$C$5),0)&"" | Q28: =VLOOKUP($C27,'2025年度(D1前期)'!$B$5:$N$208,COLUMN('2025年度(D1前期)'!$C$5),0)&"" | S28: =VLOOKUP($C27,'2025年度(D23前期)'!$B$5:$N$208,COLUMN('2025年度(D23前期)'!$C$5),0)&"" | Z28: =A28 -> １時限（09：20～10：50）
B29: 教 官 | C29: =IFERROR(VLOOKUP(C28,科目・教員!$A$1:$B$357,2,0),"") | E29: =IFERROR(VLOOKUP(E28,科目・教員!$A$1:$B$357,2,0),"") | G29: =IFERROR(VLOOKUP(G28,科目・教員!$A$1:$B$357,2,0),"") | I29: =IFERROR(VLOOKUP(I28,科目・教員!$A$1:$B$357,2,0),"") | K29: =IFERROR(VLOOKUP(K28,科目・教員!$A$1:$B$357,2,0),"") | M29: =IFERROR(VLOOKUP(M28,科目・教員!$A$1:$B$357,2,0),"") | O29: =IFERROR(VLOOKUP(O28,科目・教員!$A$1:$B$357,2,0),"") | Q29: =IFERROR(VLOOKUP(Q28,科目・教員!$A$1:$B$357,2,0),"") | S29: =IFERROR(VLOOKUP(S28,科目・教員!$A$1:$B$357,2,0),"")
B30: 使用教室 | C30: =VLOOKUP($C27,'2025年度(1年前期)'!$B$5:$N$208,COLUMN('2025年度(1年前期)'!$C$5)+1,0)&"" | E30: =VLOOKUP($C27,'2025年度(2年前期)'!$B$5:$N$208,COLUMN('2025年度(2年前期)'!$C$5)+1,0)&"" | G30: =VLOOKUP($C27,'2025年度(3年前期)'!$B$5:$N$208,COLUMN('2025年度(3年前期)'!$C$5)+1,0)&"" -> 講堂前ロビー | I30: =VLOOKUP($C27,'2025年度(4年前期)'!$B$5:$N$208,COLUMN('2025年度(4年前期)'!$C$5)+1,0)&"" -> 講堂前ロビー | K30: =VLOOKUP($C27,'2025年度(助産前期)'!$B$5:$N$208,COLUMN('2025年度(助産前期)'!$C$5)+1,0)&"" | M30: =VLOOKUP($C27,'2025年度(M1前期)'!$B$5:$N$208,COLUMN('2025年度(M1前期)'!C$5)+1,0)&"" | O30: =VLOOKUP($C27,'2025年度(M2前期)'!$B$5:$N$208,COLUMN('2025年度(M2前期)'!$C$5)+1,0)&"" | Q30: =VLOOKUP($C27,'2025年度(D1前期)'!$B$5:$N$208,COLUMN('2025年度(D1前期)'!$C$5)+1,0)&"" | S30: =VLOOKUP($C27,'2025年度(D23前期)'!$B$5:$N$208,COLUMN('2025年度(D23前期)'!$C$5)+1,0)&""
B31: 備 考
A32: ２時限（11：00～12：30） | B32: 科目名 | C32: =VLOOKUP($C27,'2025年度(1年前期)'!$B$5:$N$208,COLUMN('2025年度(1年前期)'!$E$5),0)&"" | E32: =VLOOKUP($C27,'2025年度(2年前期)'!$B$5:$N$208,COLUMN('2025年度(2年前期)'!$E$5),0)&"" -> 履修/学生生活/キャリアガイダンス | G32: =VLOOKUP($C27,'2025年度(3年前期)'!$B$5:$N$208,COLUMN('2025年度(3年前期)'!$E$5),0)&"" -> 履修/学生生活/キャリアガイダンス | I32: =VLOOKUP($C27,'2025年度(4年前期)'!$B$5:$N$208,COLUMN('2025年度(4年前期)'!$E$5),0)&"" -> 履修/学生生活/キャリアガイダンス | K32: =VLOOKUP($C27,'2025年度(助産前期)'!$B$5:$N$208,COLUMN('2025年度(助産前期)'!$E$5),0)&"" | M32: =VLOOKUP($C27,'2025年度(M1前期)'!$B$5:$N$208,COLUMN('2025年度(M1前期)'!$E$5),0)&"" | O32: =VLOOKUP($C27,'2025年度(M2前期)'!$B$5:$N$208,COLUMN('2025年度(M2前期)'!$E$5),0)&"" | Q32: =VLOOKUP($C27,'2025年度(D1前期)'!$B$5:$N$208,COLUMN('2025年度(D1前期)'!$E$5),0)&"" | S32: =VLOOKUP($C27,'2025年度(D23前期)'!$B$5:$N$208,COLUMN('2025年度(D23前期)'!$E$5),0)&"" | Z32: =A32 -> ２時限（11：00～12：30） | AG32: 2年生ガイダンス | AW32: 3年生ガイダンス | BK32: 4年生ガイダンス
B33: 教 官 | C33: =IFERROR(VLOOKUP(C32,科目・教員!$A$1:$B$357,2,0),"") | E33: =IFERROR(VLOOKUP(E32,科目・教員!$A$1:$B$357,2,0),"") | G33: =IFERROR(VLOOKUP(G32,科目・教員!$A$1:$B$357,2,0),"") | I33: =IFERROR(VLOOKUP(I32,科目・教員!$A$1:$B$357,2,0),"") | K33: =IFERROR(VLOOKUP(K32,科目・教員!$A$1:$B$357,2,0),"") | M33: =IFERROR(VLOOKUP(M32,科目・教員!$A$1:$B$357,2,0),"") | O33: =IFERROR(VLOOKUP(O32,科目・教員!$A$1:$B$357,2,0),"") | Q33: =IFERROR(VLOOKUP(Q32,科目・教員!$A$1:$B$357,2,0),"") | S33: =IFERROR(VLOOKUP(S32,科目・教員!$A$1:$B$357,2,0),"")
B34: 使用教室 | C34: =VLOOKUP($C27,'2025年度(1年前期)'!$B$5:$N$208,COLUMN('2025年度(1年前期)'!$E$5)+1,0)&"" | E34: =VLOOKUP($C27,'2025年度(2年前期)'!$B$5:$N$208,COLUMN('2025年度(2年前期)'!$E$5)+1,0)&"" -> 201 | G34: =VLOOKUP($C27,'2025年度(3年前期)'!$B$5:$N$208,COLUMN('2025年度(3年前期)'!$E$5)+1,0)&"" -> 301 | I34: =VLOOKUP($C27,'2025年度(4年前期)'!$B$5:$N$208,COLUMN('2025年度(4年前期)'!$E$5)+1,0)&"" -> 大講義室 | K34: =VLOOKUP($C27,'2025年度(助産前期)'!$B$5:$N$208,COLUMN('2025年度(助産前期)'!$E$5)+1,0)&"" | M34: =VLOOKUP($C27,'2025年度(M1前期)'!$B$5:$N$208,COLUMN('2025年度(M1前期)'!$E$5)+1,0)&"" | O34: =VLOOKUP($C27,'2025年度(M2前期)'!$B$5:$N$208,COLUMN('2025年度(M2前期)'!$E$5)+1,0)&"" | Q34: =VLOOKUP($C27,'2025年度(D1前期)'!$B$5:$N$208,COLUMN('2025年度(D1前期)'!$E$5)+1,0)&"" | S34: =VLOOKUP($C27,'2025年度(D23前期)'!$B$5:$N$208,COLUMN('2025年度(D23前期)'!$E$5)+1,0)&""
B35: 備 考
A36: 昼休み（12：30～13：30） | B36: 活動名 | Z36: =A36 -> 昼休み（12：30～13：30）
B37: 責任者
B38: 使用教室
B39: 備 考
A40: ３時限（13：30～15：00） | B40: 科目名 | C40: =VLOOKUP($C27,'2025年度(1年前期)'!$B$5:$N$208,COLUMN('2025年度(1年前期)'!$G$5),0)&"" | E40: =VLOOKUP($C27,'2025年度(2年前期)'!$B$5:$N$208,COLUMN('2025年度(2年前期)'!$G$5),0)&"" -> 必修科目教科書販売 | G40: =VLOOKUP($C27,'2025年度(3年前期)'!$B$5:$N$208,COLUMN('2025年度(3年前期)'!$G$5),0)&"" | I40: =VLOOKUP($C27,'2025年度(4年前期)'!$B$5:$N$208,COLUMN('2025年度(4年前期)'!$G$5),0)&"" | K40: =VLOOKUP($C27,'2025年度(助産前期)'!$B$5:$N$208,COLUMN('2025年度(助産前期)'!$G$5),0)&"" -> 助産学概論 | M40: =VLOOKUP($C27,'2025年度(M1前期)'!$B$5:$N$208,COLUMN('2025年度(M1前期)'!$G$5),0)&"" | O40: =VLOOKUP($C27,'2025年度(M2前期)'!$B$5:$N$208,COLUMN('2025年度(M2前期)'!$G$5),0)&"" | Q40: =VLOOKUP($C27,'2025年度(D1前期)'!$B$5:$N$208,COLUMN('2025年度(D1前期)'!$G$5),0)&"" | S40: =VLOOKUP($C27,'2025年度(D23前期)'!$B$5:$N$208,COLUMN('2025年度(D23前期)'!$G$5),0)&"" | U40: 講堂 | Z40: =A40 -> ３時限（13：30～15：00） | AF40: 入学式 伴奏練習 | AZ40: 助産学概論
...

Sheet 2025年5月
A1: 45778 | C1: １年 | E1: ２年 | G1: ３年 | I1: ４年 | K1: 助産 | M1: 研究課程部 Ｍ１ | O1: 研究課程部 Ｍ２ | Q1: 研究課程部 Ｄ１ | S1: 研究課程部 Ｄ２３ | U1: =A1 -> 45778 | V1: 授業外その他教室等管理スケジュール | AA1: １階 | AG1: ２階 | AW1: ３階 | BI1: ４階 | BK1: 体育棟 | BM1: 福利棟 | BN1: 研修棟
C2: =A1 -> 45778 | U2: =C2 -> 45778 | AA2: 101 | AB2: 102 | AC2: 103 | AD2: 在宅実習室 | AE2: 成人実習室 | AF2: 講堂 | AG2: 201 | AH2: 202 | AI2: 203 | AJ2: 204 | AK2: 205 | AL2: 基礎実習室 | AM2: 母性・小児実習室 | AN2: 演習21 | AO2: 演習22 | AP2: 演習23 | AQ2: 演習24 | AR2: 演習25 | AS2: 演習26 | AT2: 演習27 | AU2: 演習28 | AV2: 演習29 | AW2: 301 | AX2: 302 | AY2: 303 | AZ2: 304 | BA2: 臨床１ | BB2: 臨床２ | BC2: LL1 | BD2: LL2 | BE2: 実験室 | BF2: 情報処理室 | BG2: 演習31 | BH2: 演習32 | BI2: セミナー室１ | BJ2: セミナー室２ | BK2: 大講義室 | BL2: アリーナ | BM2: 多目的ルーム | BN2: 研修１ | BO2: 研修３ | BP2: 研修４ | BQ2: 研修５ | BR2: 研修６ | BS2: 研修７ | BT2: 視聴覚室
A3: １時限（09：20～10：50） | B3: 科目名 | C3: =VLOOKUP($C2,'2025年度(1年前期)'!$B$5:$N$208,COLUMN('2025年度(1年前期)'!$C$5),0)&"" -> 英語Ⅱ(C) 情報リテラシー(AB) | E3: =VLOOKUP($C2,'2025年度(2年前期)'!$B$5:$N$208,COLUMN('2025年度(2年前期)'!$C$5),0)&"" -> マスコミュニケーション論 | G3: =VLOOKUP($C2,'2025年度(3年前期)'!$B$5:$N$208,COLUMN('2025年度(3年前期)'!$C$5),0)&"" -> 看護実践と研究成果の活用 | I3: =VLOOKUP($C2,'2025年度(4年前期)'!$B$5:$N$208,COLUMN('2025年度(4年前期)'!$C$5),0)&"" | K3: =VLOOKUP($C2,'2025年度(助産前期)'!$B$5:$N$208,COLUMN('2025年度(助産前期)'!$C$5),0)&"" -> 助産学演習Ⅱ | M3: =VLOOKUP($C2,'2025年度(M1前期)'!$B$5:$N$208,COLUMN('2025年度(M1前期)'!$C$5),0)&"" -> 成育看護学特論Ａ－Ⅰ 感染管理看護学特論Ａ－Ⅱ 精神看護学特論Ａ－Ⅱ | O3: =VLOOKUP($C2,'2025年度(M2前期)'!$B$5:$N$208,COLUMN('2025年度(M2前期)'!$C$5),0)&"" -> 長寿看護学演習Ａ－Ⅱ | Q3: =VLOOKUP($C2,'2025年度(D1前期)'!$B$5:$N$208,COLUMN('2025年度(D1前期)'!$C$5),0)&"" -> 質的看護学研究法 | S3: =VLOOKUP($C2,'2025年度(D23前期)'!$B$5:$N$208,COLUMN('2025年度(D23前期)'!$C$5),0)&"" -> 特別研究 | U3: 1限 | Z3: =A3 -> １時限（09：20～10：50） | AA3: マスコミュニケーション論 | AE3: 面接練習 | AG3: 情報リテラシー | AH3: 英語ⅡC | AM3: 助産学演習Ⅱ | BA3: 質的看護学研究法 | BB3: 成育看護学特論A-Ⅰ | BI3: 精神看護学特論Ａ－Ⅱ | BK3: 看護実践と研究成果の活用
B4: 教 官 | C4: =IFERROR(VLOOKUP(C3,科目・教員!$A$1:$B$357,2,0),"") | E4: =IFERROR(VLOOKUP(E3,科目・教員!$A$1:$B$357,2,0),"") -> 飯野 勝己 | G4: =IFERROR(VLOOKUP(G3,科目・教員!$A$1:$B$357,2,0),"") -> 西岡 みどり | I4: =IFERROR(VLOOKUP(I3,科目・教員!$A$1:$B$357,2,0),"") | K4: =IFERROR(VLOOKUP(K3,科目・教員!$A$1:$B$357,2,0),"") -> 日置 智華子 | M4: =IFERROR(VLOOKUP(M3,科目・教員!$A$1:$B$357,2,0),"") | O4: =IFERROR(VLOOKUP(O3,科目・教員!$A$1:$B$357,2,0),"") | Q4: =IFERROR(VLOOKUP(Q3,科目・教員!$A$1:$B$357,2,0),"") -> 萱間 真美 | S4: =IFERROR(VLOOKUP(S3,科目・教員!$A$1:$B$357,2,0),"") | U4: 面接練習
B5: 使用教室 | C5: =VLOOKUP($C2,'2025年度(1年前期)'!$B$5:$N$208,COLUMN('2025年度(1年前期)'!$C$5)+1,0)&"" -> 英C:202 情報:201 | E5: =VLOOKUP($C2,'2025年度(2年前期)'!$B$5:$N$208,COLUMN('2025年度(2年前期)'!$C$5)+1,0)&"" -> 101 | G5: =VLOOKUP($C2,'2025年度(3年前期)'!$B$5:$N$208,COLUMN('2025年度(3年前期)'!$C$5)+1,0)&"" -> 大講義室 | I5: =VLOOKUP($C2,'2025年度(4年前期)'!$B$5:$N$208,COLUMN('2025年度(4年前期)'!$C$5)+1,0)&"" | K5: =VLOOKUP($C2,'2025年度(助産前期)'!$B$5:$N$208,COLUMN('2025年度(助産前期)'!$C$5)+1,0)&"" -> 母小実 | M5: =VLOOKUP($C2,'2025年度(M1前期)'!$B$5:$N$208,COLUMN('2025年度(M1前期)'!C$5)+1,0)&"" -> 成育:臨床講義室2 感染：別途指定 精神:セミナールーム1 | O5: =VLOOKUP($C2,'2025年度(M2前期)'!$B$5:$N$208,COLUMN('2025年度(M2前期)'!$C$5)+1,0)&"" -> 別途指定 | Q5: =VLOOKUP($C2,'2025年度(D1前期)'!$B$5:$N$208,COLUMN('2025年度(D1前期)'!$C$5)+1,0)&"" -> 臨床講義室1 | S5: =VLOOKUP($C2,'2025年度(D23前期)'!$B$5:$N$208,COLUMN('2025年度(D23前期)'!$C$5)+1,0)&"" | U5: 成人実
B6: 備 考 | C6: 非常勤講師控室A | U6: 長岡先生
A7: ２時限（11：00～12：30） | B7: 科目名 | C7: =VLOOKUP($C2,'2025年度(1年前期)'!$B$5:$N$208,COLUMN('2025年度(1年前期)'!$E$5),0)&"" -> 英語Ⅱ(AB) 情報リテラシー(CD) | E7: =VLOOKUP($C2,'2025年度(2年前期)'!$B$5:$N$208,COLUMN('2025年度(2年前期)'!$E$5),0)&"" -> 遺伝と健康 | G7: =VLOOKUP($C2,'2025年度(3年前期)'!$B$5:$N$208,COLUMN('2025年度(3年前期)'!$E$5),0)&"" -> 看護実践と研究成果の活用 | I7: =VLOOKUP($C2,'2025年度(4年前期)'!$B$5:$N$208,COLUMN('2025年度(4年前期)'!$E$5),0)&"" | K7: =VLOOKUP($C2,'2025年度(助産前期)'!$B$5:$N$208,COLUMN('2025年度(助産前期)'!$E$5),0)&"" -> 助産学演習Ⅱ | M7: =VLOOKUP($C2,'2025年度(M1前期)'!$B$5:$N$208,COLUMN('2025年度(M1前期)'!$E$5),0)&"" -> 成育看護学特論Ａ－Ⅰ 感染管理看護学特論Ａ－Ⅱ 精神看護学特論Ａ－Ⅱ | O7: =VLOOKUP($C2,'2025年度(M2前期)'!$B$5:$N$208,COLUMN('2025年度(M2前期)'!$E$5),0)&"" -> 長寿看護学演習Ａ－Ⅱ | Q7: =VLOOKUP($C2,'2025年度(D1前期)'!$B$5:$N$208,COLUMN('2025年度(D1前期)'!$E$5),0)&"" -> 質的看護学研究法 | S7: =VLOOKUP($C2,'2025年度(D23前期)'!$B$5:$N$208,COLUMN('2025年度(D23前期)'!$E$5),0)&"" -> 特別研究 | U7: 2限 | Z7: =A7 -> ２時限（11：00～12：30） | AA7: 遺伝と健康 | AG7: 情報リテラシー | AH7: 英語ⅡA | AM7: 助産学演習Ⅱ | AW7: 英語ⅡB | AX7: 卒研(老年)古川先生 | BA7: 質的看護学研究法 | BB7: 成育看護学特論A-Ⅰ | BI7: 精神看護学特論Ａ－Ⅱ | BK7: 看護実践と研究成果の活用
B8: 教 官 | C8: =IFERROR(VLOOKUP(C7,科目・教員!$A$1:$B$357,2,0),"") | E8: =IFERROR(VLOOKUP(E7,科目・教員!$A$1:$B$357,2,0),"") -> 井上 健 | G8: =IFERROR(VLOOKUP(G7,科目・教員!$A$1:$B$357,2,0),"") -> 西岡 みどり | I8: =IFERROR(VLOOKUP(I7,科目・教員!$A$1:$B$357,2,0),"") | K8: =IFERROR(VLOOKUP(K7,科目・教員!$A$1:$B$357,2,0),"") -> 日置 智華子 | M8: =IFERROR(VLOOKUP(M7,科目・教員!$A$1:$B$357,2,0),"") | O8: =IFERROR(VLOOKUP(O7,科目・教員!$A$1:$B$357,2,0),"") | Q8: =IFERROR(VLOOKUP(Q7,科目・教員!$A$1:$B$357,2,0),"") -> 萱間 真美 | S8: =IFERROR(VLOOKUP(S7,科目・教員!$A$1:$B$357,2,0),"") | U8: 卒研(老年)
B9: 使用教室 | C9: =VLOOKUP($C2,'2025年度(1年前期)'!$B$5:$N$208,COLUMN('2025年度(1年前期)'!$E$5)+1,0)&"" -> 英A:202 英B:301 情報:201 | E9: =VLOOKUP($C2,'2025年度(2年前期)'!$B$5:$N$208,COLUMN('2025年度(2年前期)'!$E$5)+1,0)&"" -> 101 | G9: =VLOOKUP($C2,'2025年度(3年前期)'!$B$5:$N$208,COLUMN('2025年度(3年前期)'!$E$5)+1,0)&"" -> 大講義室 | I9: =VLOOKUP($C2,'2025年度(4年前期)'!$B$5:$N$208,COLUMN('2025年度(4年前期)'!$E$5)+1,0)&"" | K9: =VLOOKUP($C2,'2025年度(助産前期)'!$B$5:$N$208,COLUMN('2025年度(助産前期)'!$E$5)+1,0)&"" -> 母小実 | M9: =VLOOKUP($C2,'2025年度(M1前期)'!$B$5:$N$208,COLUMN('2025年度(M1前期)'!$E$5)+1,0)&"" -> 成育:臨床講義室2 感染：別途指定 精神:セミナールーム1 | O9: =VLOOKUP($C2,'2025年度(M2前期)'!$B$5:$N$208,COLUMN('2025年度(M2前期)'!$E$5)+1,0)&"" -> 別途指定 | Q9: =VLOOKUP($C2,'2025年度(D1前期)'!$B$5:$N$208,COLUMN('2025年度(D1前期)'!$E$5)+1,0)&"" -> 臨床講義室1 | S9: =VLOOKUP($C2,'2025年度(D23前期)'!$B$5:$N$208,COLUMN('2025年度(D23前期)'!$E$5)+1,0)&"" | U9: 302教室
B10: 備 考 | C10: 非常勤講師控室A | E10: 非常勤講師控室B | U10: 古川先生
A11: 昼休み（12：30～13：30） | B11: 活動名 | Z11: =A11 -> 昼休み（12：30～13：30）
B12: 責任者
B13: 使用教室
B14: 備 考
A15: ３時限（13：30～15：00） | B15: 科目名 | C15: =VLOOKUP($C2,'2025年度(1年前期)'!$B$5:$N$208,COLUMN('2025年度(1年前期)'!$G$5),0)&"" -> 看護学概論 | E15: =VLOOKUP($C2,'2025年度(2年前期)'!$B$5:$N$208,COLUMN('2025年度(2年前期)'!$G$5),0)&"" -> フィジカルアセスメント | G15: =VLOOKUP($C2,'2025年度(3年前期)'!$B$5:$N$208,COLUMN('2025年度(3年前期)'!$G$5),0)&"" -> 小児看護援助論Ⅱ | I15: =VLOOKUP($C2,'2025年度(4年前期)'!$B$5:$N$208,COLUMN('2025年度(4年前期)'!$G$5),0)&"" -> 国際看護活動論 | K15: =VLOOKUP($C2,'2025年度(助産前期)'!$B$5:$N$208,COLUMN('2025年度(助産前期)'!$G$5),0)&"" | M15: =VLOOKUP($C2,'2025年度(M1前期)'!$B$5:$N$208,COLUMN('2025年度(M1前期)'!$G$5),0)&"" -> 長寿看護学特論Ａ－Ⅰ 感染管理看護学演習Ａ－Ⅰ 精神看護学演習Ａ－Ⅰ | O15: =VLOOKUP($C2,'2025年度(M2前期)'!$B$5:$N$208,COLUMN('2025年度(M2前期)'!$G$5),0)&"" -> 特別研究 | Q15: =VLOOKUP($C2,'2025年度(D1前期)'!$B$5:$N$208,COLUMN('2025年度(D1前期)'!$G$5),0)&"" | S15: =VLOOKUP($C2,'2025年度(D23前期)'!$B$5:$N$208,COLUMN('2025年度(D23前期)'!$G$5),0)&"" -> 特別研究 | Z15: =A15 -> ３時限（13：30～15：00） | AA15: フィジカルアセスメント | AE15: フィジカルアセスメント | AG15: 看護学概論 | AH15: フィジカルアセスメント | AW15: 国際看護活動論 | BA15: 長寿看護学特論A-Ⅰ | BB15: 精神看護学演習Ａ－Ⅰ | BK15: 小児看護援助論Ⅱ
B16: 教 官 | C16: =IFERROR(VLOOKUP(C15,科目・教員!$A$1:$B$357,2,0),"") -> 矢富 有見子 | E16: =IFERROR(VLOOKUP(E15,科目・教員!$A$1:$B$357,2,0),"") -> 梅田 亜矢 | G16: =IFERROR(VLOOKUP(G15,科目・教員!$A$1:$B$357,2,0),"") -> 遠藤 数江 | I16: =IFERROR(VLOOKUP(I15,科目・教員!$A$1:$B$357,2,0),"") -> 須藤 恭子 | K16: =IFERROR(VLOOKUP(K15,科目・教員!$A$1:$B$357,2,0),"") | M16: =IFERROR(VLOOKUP(M15,科目・教員!$A$1:$B$357,2,0),"") | O16: =IFERROR(VLOOKUP(O15,科目・教員!$A$1:$B$357,2,0),"") | Q16: =IFERROR(VLOOKUP(Q15,科目・教員!$A$1:$B$357,2,0),"") | S16: =IFERROR(VLOOKUP(S15,科目・教員!$A$1:$B$357,2,0),"")
B17: 使用教室 | C17: =VLOOKUP($C2,'2025年度(1年前期)'!$B$5:$N$208,COLUMN('2025年度(1年前期)'!$G$5)+1,0)&"" -> 201 | E17: =VLOOKUP($C2,'2025年度(2年前期)'!$B$5:$N$208,COLUMN('2025年度(2年前期)'!$G$5)+1,0)&"" -> 101･202･成人実 | G17: =VLOOKUP($C2,'2025年度(3年前期)'!$B$5:$N$208,COLUMN('2025年度(3年前期)'!$G$5)+1,0)&"" -> 大講義室 | I17: =VLOOKUP($C2,'2025年度(4年前期)'!$B$5:$N$208,COLUMN('2025年度(4年前期)'!$G$5)+1,0)&"" -> 301 | K17: =VLOOKUP($C2,'2025年度(助産前期)'!$B$5:$N$208,COLUMN('2025年度(助産前期)'!$G$5)+1,0)&"" | M17: =VLOOKUP($C2,'2025年度(M1前期)'!$B$5:$N$208,COLUMN('2025年度(M1前期)'!$G$5)+1,0)&"" -> 長寿:臨床講義室1 感染:別途指定 精神:臨床講義室2 | O17: =VLOOKUP($C2,'2025年度(M2前期)'!$B$5:$N$208,COLUMN('2025年度(M2前期)'!$G$5)+1,0)&"" | Q17: =VLOOKUP($C2,'2025年度(D1前期)'!$B$5:$N$208,COLUMN('2025年度(D1前期)'!$G$5)+1,0)&"" | S17: =VLOOKUP($C2,'2025年度(D23前期)'!$B$5:$N$208,COLUMN('2025年度(D23前期)'!$G$5)+1,0)&""
B18: 備 考
A19: ４時限（15：10～16：40） | B19: 科目名 | C19: =VLOOKUP($C2,'2025年度(1年前期)'!$B$5:$N$208,COLUMN('2025年度(1年前期)'!$I$5),0)&"" -> 食の科学 | E19: =VLOOKUP($C2,'2025年度(2年前期)'!$B$5:$N$208,COLUMN('2025年度(2年前期)'!$I$5),0)&"" -> フィジカルアセスメント | G19: =VLOOKUP($C2,'2025年度(3年前期)'!$B$5:$N$208,COLUMN('2025年度(3年前期)'!$I$5),0)&"" -> 小児看護援助論Ⅱ | I19: =VLOOKUP($C2,'2025年度(4年前期)'!$B$5:$N$208,COLUMN('2025年度(4年前期)'!$I$5),0)&"" -> 国際看護学実習Ⅱオリ② | K19: =VLOOKUP($C2,'2025年度(助産前期)'!$B$5:$N$208,COLUMN('2025年度(助産前期)'!$I$5),0)&"" | M19: =VLOOKUP($C2,'2025年度(M1前期)'!$B$5:$N$208,COLUMN('2025年度(M1前期)'!$I$5),0)&"" -> 長寿看護学特論Ａ－Ⅰ 感染管理看護学演習Ａ－Ⅰ 精神看護学演習Ａ－Ⅰ | O19: =VLOOKUP($C2,'2025年度(M2前期)'!$B$5:$N$208,COLUMN('2025年度(M2前期)'!$I$5),0)&"" -> 特別研究 | Q19: =VLOOKUP($C2,'2025年度(D1前期)'!$B$5:$N$208,COLUMN('2025年度(D1前期)'!$I$5),0)&"" | S19: =VLOOKUP($C2,'2025年度(D23前期)'!$B$5:$N$208,COLUMN('2025年度(D23前期)'!$I$5),0)&"" -> 特別研究 | U19: 4限 | Z19: =A19 -> ４時限（15：10～16：40） | AA19: フィジカルアセスメント | AE19: フィジカルアセスメント | AG19: 食の科学 | AH19: フィジカルアセスメント | AW19: 国際看護学実習Ⅱオリエンテーション | BA19: 長寿看護学特論A-Ⅰ | BB19: 精神看護学演習Ａ－Ⅰ | BJ19: M2今野 | BK19: 小児看護援助論Ⅱ
B20: 教 官 | C20: =IFERROR(VLOOKUP(C19,科目・教員!$A$1:$B$357,2,0),"") -> 本間 典子 | E20: =IFERROR(VLOOKUP(E19,科目・教員!$A$1:$B$357,2,0),"") -> 梅田 亜矢 | G20: =IFERROR(VLOOKUP(G19,科目・教員!$A$1:$B$357,2,0),"") -> 遠藤 数江 | I20: =IFERROR(VLOOKUP(I19,科目・教員!$A$1:$B$357,2,0),"") | K20: =IFERROR(VLOOKUP(K19,科目・教員!$A$1:$B$357,2,0),"") | M20: =IFERROR(VLOOKUP(M19,科目・教員!$A$1:$B$357,2,0),"") | O20: =IFERROR(VLOOKUP(O19,科目・教員!$A$1:$B$357,2,0),"") | Q20: =IFERROR(VLOOKUP(Q19,科目・教員!$A$1:$B$357,2,0),"") | S20: =IFERROR(VLOOKUP(S19,科目・教員!$A$1:$B$357,2,0),"") | U20: ゼミ
B21: 使用教室 | C21: =VLOOKUP($C2,'2025年度(1年前期)'!$B$5:$N$208,COLUMN('2025年度(1年前期)'!$I$5)+1,0)&"" -> 201 | E21: =VLOOKUP($C2,'2025年度(2年前期)'!$B$5:$N$208,COLUMN('2025年度(2年前期)'!$I$5)+1,0)&"" -> 101･202･成人実 | G21: =VLOOKUP($C2,'2025年度(3年前期)'!$B$5:$N$208,COLUMN('2025年度(3年前期)'!$I$5)+1,0)&"" -> 大講義室 | I21: =VLOOKUP($C2,'2025年度(4年前期)'!$B$5:$N$208,COLUMN('2025年度(4年前期)'!$I$5)+1,0)&"" -> 301 | K21: =VLOOKUP($C2,'2025年度(助産前期)'!$B$5:$N$208,COLUMN('2025年度(助産前期)'!$I$5)+1,0)&"" | M21: =VLOOKUP($C2,'2025年度(M1前期)'!$B$5:$N$208,COLUMN('2025年度(M1前期)'!$I$5)+1,0)&"" -> 長寿:臨床講義室1 感染:別途指定 精神:臨床講義室2 | O21: =VLOOKUP($C2,'2025年度(M2前期)'!$B$5:$N$208,COLUMN('2025年度(M2前期)'!$I$5)+1,0)&"" | Q21: =VLOOKUP($C2,'2025年度(D1前期)'!$B$5:$N$208,COLUMN('2025年度(D1前期)'!$I$5)+1,0)&"" | S21: =VLOOKUP($C2,'2025年度(D23前期)'!$B$5:$N$208,COLUMN('2025年度(D23前期)'!$I$5)+1,0)&"" | U21: M2今野
B22: 備 考 | U22: セミナールーム2
A23: ５時限（16：50～18：20） | B23: 科目名 | C23: =VLOOKUP($C2,'2025年度(1年前期)'!$B$5:$N$208,COLUMN('2025年度(1年前期)'!$K$5),0)&"" -> フランス語 | E23: =VLOOKUP($C2,'2025年度(2年前期)'!$B$5:$N$208,COLUMN('2025年度(2年前期)'!$K$5),0)&"" | G23: =VLOOKUP($C2,'2025年度(3年前期)'!$B$5:$N$208,COLUMN('2025年度(3年前期)'!$K$5),0)&"" | I23: =VLOOKUP($C2,'2025年度(4年前期)'!$B$5:$N$208,COLUMN('2025年度(4年前期)'!$K$5),0)&"" -> 卒業研究Ⅰ | K23: =VLOOKUP($C2,'2025年度(助産前期)'!$B$5:$N$208,COLUMN('2025年度(助産前期)'!$K$5),0)&"" | M23: =VLOOKUP($C2,'2025年度(M1前期)'!$B$5:$N$208,COLUMN('2025年度(M1前期)'!$K$5),0)&"" | O23: =VLOOKUP($C2,'2025年度(M2前期)'!$B$5:$N$208,COLUMN('2025年度(M2前期)'!$K$5),0)&"" | Q23: =VLOOKUP($C2,'2025年度(D1前期)'!$B$5:$N$208,COLUMN('2025年度(D1前期)'!$K$5),0)&"" | S23: =VLOOKUP($C2,'2025年度(D23前期)'!$B$5:$N$208,COLUMN('2025年度(D23前期)'!$K$5),0)&"" | U23: 5限 | V23: 5限 | Z23: =A23 -> ５時限（16：50～18：20） | AG23: フランス語 | AX23: 長岡先生卒研 | BI23: M2栗原
B24: 教 官 | C24: =IFERROR(VLOOKUP(C23,科目・教員!$A$1:$B$357,2,0),"") -> 小西 英則 | E24: =IFERROR(VLOOKUP(E23,科目・教員!$A$1:$B$357,2,0),"") | G24: =IFERROR(VLOOKUP(G23,科目・教員!$A$1:$B$357,2,0),"") | I24: =IFERROR(VLOOKUP(I23,科目・教員!$A$1:$B$357,2,0),"") -> 各担当教員 | K24: =IFERROR(VLOOKUP(K23,科目・教員!$A$1:$B$357,2,0),"") | M24: =IFERROR(VLOOKUP(M23,科目・教員!$A$1:$B$357,2,0),"") | O24: =IFERROR(VLOOKUP(O23,科目・教員!$A$1:$B$357,2,0),"") | Q24: =IFERROR(VLOOKUP(Q23,科目・教員!$A$1:$B$357,2,0),"") | S24: =IFERROR(VLOOKUP(S23,科目・教員!$A$1:$B$357,2,0),"") | U24: 長寿ゼミ | V24: 長岡先生卒研
B25: 使用教室 | C25: =VLOOKUP($C2,'2025年度(1年前期)'!$B$5:$N$208,COLUMN('2025年度(1年前期)'!$K$5)+1,0)&"" -> 201 | E25: =VLOOKUP($C2,'2025年度(2年前期)'!$B$5:$N$208,COLUMN('2025年度(2年前期)'!$K$5)+1,0)&"" | G25: =VLOOKUP($C2,'2025年度(3年前期)'!$B$5:$N$208,COLUMN('2025年度(3年前期)'!$K$5)+1,0)&"" | I25: =VLOOKUP($C2,'2025年度(4年前期)'!$B$5:$N$208,COLUMN('2025年度(4年前期)'!$K$5)+1,0)&"" | K25: =VLOOKUP($C2,'2025年度(助産前期)'!$B$5:$N$208,COLUMN('2025年度(助産前期)'!$K$5)+1,0)&"" | M25: =VLOOKUP($C2,'2025年度(M1前期)'!$B$5:$N$208,COLUMN('2025年度(M1前期)'!$K$5)+1,0)&"" | O25: =VLOOKUP($C2,'2025年度(M2前期)'!$B$5:$N$208,COLUMN('2025年度(M2前期)'!$K$5)+1,0)&"" | Q25: =VLOOKUP($C2,'2025年度(D1前期)'!$B$5:$N$208,COLUMN('2025年度(D1前期)'!$K$5)+1,0)&"" | S25: =VLOOKUP($C2,'2025年度(D23前期)'!$B$5:$N$208,COLUMN('2025年度(D23前期)'!$K$5)+1,0)&"" | U25: M2栗原 | V25: 302教室
B26: 備 考 | C26: 非常勤講師控室A | U26: セミナールーム1
C27: =C2+1 -> 45779 | U27: =C27 -> 45779 | AA27: 101 | AB27: 102 | AC27: 103 | AD27: 在宅実習室 | AE27: 成人実習室 | AF27: 講堂 | AG27: 201 | AH27: 202 | AI27: 203 | AJ27: 204 | AK27: 205 | AL27: 基礎実習室 | AM27: 母性・小児実習室 | AN27: 演習21 | AO27: 演習22 | AP27: 演習23 | AQ27: 演習24 | AR27: 演習25 | AS27: 演習26 | AT27: 演習27 | AU27: 演習28 | AV27: 演習29 | AW27: 301 | AX27: 302 | AY27: 303 | AZ27: 304 | BA27: 臨床１ | BB27: 臨床２ | BC27: LL1 | BD27: LL2 | BE27: 実験室 | BF27: 情報処理室 | BG27: 演習31 | BH27: 演習32 | BI27: セミナー室１ | BJ27: セミナー室２ | BK27: 大講義室 | BL27: アリーナ | BM27: 多目的ルーム | BN27: 研修１ | BO27: 研修３ | BP27: 研修４ | BQ27: 研修５ | BR27: 研修６ | BS27: 研修７ | BT27: 視聴覚室
A28: １時限（09：20～10：50） | B28: 科目名 | C28: =VLOOKUP($C27,'2025年度(1年前期)'!$B$5:$N$208,COLUMN('2025年度(1年前期)'!$C$5),0)&"" -> 生命科学 | E28: =VLOOKUP($C27,'2025年度(2年前期)'!$B$5:$N$208,COLUMN('2025年度(2年前期)'!$C$5),0)&"" -> マスコミュニケーション論 | G28: =VLOOKUP($C27,'2025年度(3年前期)'!$B$5:$N$208,COLUMN('2025年度(3年前期)'!$C$5),0)&"" -> 精神看護援助論 | I28: =VLOOKUP($C27,'2025年度(4年前期)'!$B$5:$N$208,COLUMN('2025年度(4年前期)'!$C$5),0)&"" -> 高度先駆的医療看護Ⅰ(がん看護) | K28: =VLOOKUP($C27,'2025年度(助産前期)'!$B$5:$N$208,COLUMN('2025年度(助産前期)'!$C$5),0)&"" | M28: =VLOOKUP($C27,'2025年度(M1前期)'!$B$5:$N$208,COLUMN('2025年度(M1前期)'!$C$5),0)&"" -> 政策医療看護学特論Ⅰ | O28: =VLOOKUP($C27,'2025年度(M2前期)'!$B$5:$N$208,COLUMN('2025年度(M2前期)'!$C$5),0)&"" -> 看護情報・管理学演習Ａ－Ⅱ 感染管理看護学演習Ａ－Ⅱ | Q28: =VLOOKUP($C27,'2025年度(D1前期)'!$B$5:$N$208,COLUMN('2025年度(D1前期)'!$C$5),0)&"" -> 精神看護学特論Ｂ | S28: =VLOOKUP($C27,'2025年度(D23前期)'!$B$5:$N$208,COLUMN('2025年度(D23前期)'!$C$5),0)&"" -> 特別研究 | U28: 1限 | Z28: =A28 -> １時限（09：20～10：50） | AA28: 生命科学 | AG28: マスコミュニケーション論 | AW28: 精神看護援助論 | BA28: 政策医療看護学特論Ⅰ | BI28: D3坂口 | BK28: 感染症看護論
B29: 教 官 | C29: =IFERROR(VLOOKUP(C28,科目・教員!$A$1:$B$357,2,0),"") -> 本間 典子 | E29: =IFERROR(VLOOKUP(E28,科目・教員!$A$1:$B$357,2,0),"") -> 飯野 勝己 | G29: =IFERROR(VLOOKUP(G28,科目・教員!$A$1:$B$357,2,0),"") -> 松浦 佳代 | I29: =IFERROR(VLOOKUP(I28,科目・教員!$A$1:$B$357,2,0),"") -> 飯野 京子 | K29: =IFERROR(VLOOKUP(K28,科目・教員!$A$1:$B$357,2,0),"") | M29: =IFERROR(VLOOKUP(M28,科目・教員!$A$1:$B$357,2,0),"") -> 綿貫 成明 | O29: =IFERROR(VLOOKUP(O28,科目・教員!$A$1:$B$357,2,0),"") | Q29: =IFERROR(VLOOKUP(Q28,科目・教員!$A$1:$B$357,2,0),"") | S29: =IFERROR(VLOOKUP(S28,科目・教員!$A$1:$B$357,2,0),"") | U29: D3坂口
B30: 使用教室 | C30: =VLOOKUP($C27,'2025年度(1年前期)'!$B$5:$N$208,COLUMN('2025年度(1年前期)'!$C$5)+1,0)&"" -> 101 | E30: =VLOOKUP($C27,'2025年度(2年前期)'!$B$5:$N$208,COLUMN('2025年度(2年前期)'!$C$5)+1,0)&"" -> 201 | G30: =VLOOKUP($C27,'2025年度(3年前期)'!$B$5:$N$208,COLUMN('2025年度(3年前期)'!$C$5)+1,0)&"" -> 301 | I30: =VLOOKUP($C27,'2025年度(4年前期)'!$B$5:$N$208,COLUMN('2025年度(4年前期)'!$C$5)+1,0)&"" -> 大講義室 | K30: =VLOOKUP($C27,'2025年度(助産前期)'!$B$5:$N$208,COLUMN('2025年度(助産前期)'!$C$5)+1,0)&"" | M30: =VLOOKUP($C27,'2025年度(M1前期)'!$B$5:$N$208,COLUMN('2025年度(M1前期)'!C$5)+1,0)&"" -> 臨床講義室1 | O30: =VLOOKUP($C27,'2025年度(M2前期)'!$B$5:$N$208,COLUMN('2025年度(M2前期)'!$C$5)+1,0)&"" -> 情報:別途指定 感染:別途指定 | Q30: =VLOOKUP($C27,'2025年度(D1前期)'!$B$5:$N$208,COLUMN('2025年度(D1前期)'!$C$5)+1,0)&"" -> 別途指定 | S30: =VLOOKUP($C27,'2025年度(D23前期)'!$B$5:$N$208,COLUMN('2025年度(D23前期)'!$C$5)+1,0)&"" | U30: セミナールーム1
B31: 備 考 | E31: 非常勤講師控室C
A32: ２時限（11：00～12：30） | B32: 科目名 | C32: =VLOOKUP($C27,'2025年度(1年前期)'!$B$5:$N$208,COLUMN('2025年度(1年前期)'!$E$5),0)&"" -> 文学 | E32: =VLOOKUP($C27,'2025年度(2年前期)'!$B$5:$N$208,COLUMN('2025年度(2年前期)'!$E$5),0)&"" -> 成人看護援助論Ⅰ | G32: =VLOOKUP($C27,'2025年度(3年前期)'!$B$5:$N$208,COLUMN('2025年度(3年前期)'!$E$5),0)&"" -> 精神看護援助論 | I32: =VLOOKUP($C27,'2025年度(4年前期)'!$B$5:$N$208,COLUMN('2025年度(4年前期)'!$E$5),0)&"" -> 高度先駆的医療看護Ⅲ(精神看護) | K32: =VLOOKUP($C27,'2025年度(助産前期)'!$B$5:$N$208,COLUMN('2025年度(助産前期)'!$E$5),0)&"" | M32: =VLOOKUP($C27,'2025年度(M1前期)'!$B$5:$N$208,COLUMN('2025年度(M1前期)'!$E$5),0)&"" -> 政策医療看護学特論Ⅰ | O32: =VLOOKUP($C27,'2025年度(M2前期)'!$B$5:$N$208,COLUMN('2025年度(M2前期)'!$E$5),0)&"" -> 看護情報・管理学演習Ａ－Ⅱ 感染管理看護学演習Ａ－Ⅱ | Q32: =VLOOKUP($C27,'2025年度(D1前期)'!$B$5:$N$208,COLUMN('2025年度(D1前期)'!$E$5),0)&"" -> 精神看護学特論Ｂ | S32: =VLOOKUP($C27,'2025年度(D23前期)'!$B$5:$N$208,COLUMN('2025年度(D23前期)'!$E$5),0)&"" -> 特別研究 | U32: 2限 | Z32: =A32 -> ２時限（11：00～12：30） | AA32: 文学 | AG32: 成人看護援助論Ⅰ | AL32: 周産期看護 (準備) | AM32: 周産期看護 (準備) | AW32: 精神看護援助論 | BA32: 政策医療看護学特論Ⅰ | BK32: 高度先駆的医療看護Ⅲ(精神看護)
B33: 教 官 | C33: =IFERROR(VLOOKUP(C32,科目・教員!$A$1:$B$357,2,0),"") -> 佐藤 ゆかり | E33: =IFERROR(VLOOKUP(E32,科目・教員!$A$1:$B$357,2,0),"") -> 飯野 京子 | G33: =IFERROR(VLOOKUP(G32,科目・教員!$A$1:$B$357,2,0),"") -> 松浦 佳代 | I33: =IFERROR(VLOOKUP(I32,科目・教員!$A$1:$B$357,2,0),"") -> 森 真喜子 | K33: =IFERROR(VLOOKUP(K32,科目・教員!$A$1:$B$357,2,0),"") | M33: =IFERROR(VLOOKUP(M32,科目・教員!$A$1:$B$357,2,0),"") -> 綿貫 成明 | O33: =IFERROR(VLOOKUP(O32,科目・教員!$A$1:$B$357,2,0),"") | Q33: =IFERROR(VLOOKUP(Q32,科目・教員!$A$1:$B$357,2,0),"") | S33: =IFERROR(VLOOKUP(S32,科目・教員!$A$1:$B$357,2,0),"") | U33: 周産期看護授業準備
B34: 使用教室 | C34: =VLOOKUP($C27,'2025年度(1年前期)'!$B$5:$N$208,COLUMN('2025年度(1年前期)'!$E$5)+1,0)&"" -> 101 | E34: =VLOOKUP($C27,'2025年度(2年前期)'!$B$5:$N$208,COLUMN('2025年度(2年前期)'!$E$5)+1,0)&"" -> 201 | G34: =VLOOKUP($C27,'2025年度(3年前期)'!$B$5:$N$208,COLUMN('2025年度(3年前期)'!$E$5)+1,0)&"" -> 301 | I34: =VLOOKUP($C27,'2025年度(4年前期)'!$B$5:$N$208,COLUMN('2025年度(4年前期)'!$E$5)+1,0)&"" -> 大講義室 | K34: =VLOOKUP($C27,'2025年度(助産前期)'!$B$5:$N$208,COLUMN('2025年度(助産前期)'!$E$5)+1,0)&"" | M34: =VLOOKUP($C27,'2025年度(M1前期)'!$B$5:$N$208,COLUMN('2025年度(M1前期)'!$E$5)+1,0)&"" -> 臨床講義室1 | O34: =VLOOKUP($C27,'2025年度(M2前期)'!$B$5:$N$208,COLUMN('2025年度(M2前期)'!$E$5)+1,0)&"" -> 情報:別途指定 感染:別途指定 | Q34: =VLOOKUP($C27,'2025年度(D1前期)'!$B$5:$N$208,COLUMN('2025年度(D1前期)'!$E$5)+1,0)&"" -> 別途指定 | S34: =VLOOKUP($C27,'2025年度(D23前期)'!$B$5:$N$208,COLUMN('2025年度(D23前期)'!$E$5)+1,0)&"" | U34: 基礎実･母小実
B35: 備 考 | C35: 非常勤講師控室A | U35: 日置先生
A36: 昼休み（12：30～13：30） | B36: 活動名 | Z36: =A36 -> 昼休み（12：30～13：30）
B37: 責任者
B38: 使用教室
B39: 備 考
A40: ３時限（13：30～15：00） | B40: 科目名 | C40: =VLOOKUP($C27,'2025年度(1年前期)'!$B$5:$N$208,COLUMN('2025年度(1年前期)'!$G$5),0)&"" -> 環境と健康 | E40: =VLOOKUP($C27,'2025年度(2年前期)'!$B$5:$N$208,COLUMN('2025年度(2年前期)'!$G$5),0)&"" -> 生活援助論Ⅲ | G40: =VLOOKUP($C27,'2025年度(3年前期)'!$B$5:$N$208,COLUMN('2025年度(3年前期)'!$G$5),0)&"" -> 周産期看護 | I40: =VLOOKUP($C27,'2025年度(4年前期)'!$B$5:$N$208,COLUMN('2025年度(4年前期)'!$G$5),0)&"" -> 高度先駆的医療看護Ⅴ(長寿･地域看護) | K40: =VLOOKUP($C27,'2025年度(助産前期)'!$B$5:$N$208,COLUMN('2025年度(助産前期)'!$G$5),0)&"" | M40: =VLOOKUP($C27,'2025年度(M1前期)'!$B$5:$N$208,COLUMN('2025年度(M1前期)'!$G$5),0)&"" -> 看護研究法 | O40: =VLOOKUP($C27,'2025年度(M2前期)'!$B$5:$N$208,COLUMN('2025年度(M2前期)'!$G$5),0)&"" -> 特別研究 | Q40: =VLOOKUP($C27,'2025年度(D1前期)'!$B$5:$N$208,COLUMN('2025年度(D1前期)'!$G$5),0)&"" | S40: =VLOOKUP($C27,'2025年度(D23前期)'!$B$5:$N$208,COLUMN('2025年度(D23前期)'!$G$5),0)&"" -> 特別研究 | Z40: =A40 -> ３時限（13：30～15：00） | AA40: 環境と健康 | AG40: 生活援助論Ⅲ | AL40: 周産期看護 | AM40: 周産期看護 | AW40: 周産期看護 | BA40: 看護研究法 | BF40: M2山内 | BK40: 高度先駆的医療看護Ⅴ(長寿･地域看護)
...

Sheet 2025年6月
A1: 45809 | C1: １年 | E1: ２年 | G1: ３年 | I1: ４年 | K1: 助産 | M1: 研究課程部 Ｍ１ | O1: 研究課程部 Ｍ２ | Q1: 研究課程部 Ｄ１ | S1: 研究課程部 Ｄ２３ | U1: =A1 -> 45809 | V1: 授業外その他教室等管理スケジュール | AA1: １階 | AG1: ２階 | AW1: ３階 | BI1: ４階 | BN1: 体育棟 | BP1: 福利棟 | BQ1: 研修棟
C2: =A1 -> 45809 | U2: =C2 -> 45809 | AA2: 101 | AB2: 102 | AC2: 103 | AD2: 在宅実習室 | AE2: 成人実習室 | AF2: 講堂 | AG2: 201 | AH2: 202 | AI2: 203 | AJ2: 204 | AK2: 205 | AL2: 基礎実習室 | AM2: 母性・小児実習室 | AN2: 演習21 | AO2: 演習22 | AP2: 演習23 | AQ2: 演習24 | AR2: 演習25 | AS2: 演習26 | AT2: 演習27 | AU2: 演習28 | AV2: 演習29 | AW2: 301 | AX2: 302 | AY2: 303 | AZ2: 304 | BA2: 臨床１ | BB2: 臨床２ | BC2: LL1 | BD2: LL2 | BE2: 実験室 | BF2: 情報処理室 | BG2: 演習31 | BH2: 演習32 | BI2: セミナー室1 | BJ2: セミナー室2 | BK2: セミナー室3 | BL2: セミナー室4 | BM2: セミナー室5 | BN2: 大講義室 | BO2: アリーナ | BP2: 多目的ルーム | BQ2: 研修１ | BR2: 研修３ | BS2: 研修４ | BT2: 研修５ | BU2: 研修６ | BV2: 研修７ | BW2: 視聴覚室
A3: １時限（09：20～10：50） | B3: 科目名 | C3: =VLOOKUP($C2,'2025年度(1年前期)'!$B$5:$N$208,COLUMN('2025年度(1年前期)'!$C$5),0)&"" | E3: =VLOOKUP($C2,'2025年度(2年前期)'!$B$5:$N$208,COLUMN('2025年度(2年前期)'!$C$5),0)&"" | G3: =VLOOKUP($C2,'2025年度(3年前期)'!$B$5:$N$208,COLUMN('2025年度(3年前期)'!$C$5),0)&"" | I3: =VLOOKUP($C2,'2025年度(4年前期)'!$B$5:$N$208,COLUMN('2025年度(4年前期)'!$C$5),0)&"" | K3: =VLOOKUP($C2,'2025年度(助産前期)'!$B$5:$N$208,COLUMN('2025年度(助産前期)'!$C$5),0)&"" | M3: =VLOOKUP($C2,'2025年度(M1前期)'!$B$5:$N$208,COLUMN('2025年度(M1前期)'!$C$5),0)&"" | O3: =VLOOKUP($C2,'2025年度(M2前期)'!$B$5:$N$208,COLUMN('2025年度(M2前期)'!$C$5),0)&"" | Q3: =VLOOKUP($C2,'2025年度(D1前期)'!$B$5:$N$208,COLUMN('2025年度(D1前期)'!$C$5),0)&"" | S3: =VLOOKUP($C2,'2025年度(D23前期)'!$B$5:$N$208,COLUMN('2025年度(D23前期)'!$C$5),0)&"" | Z3: =A3 -> １時限（09：20～10：50）
B4: 教 官 | C4: =IFERROR(VLOOKUP(C3,科目・教員!$A$1:$B$357,2,0),"") | E4: =IFERROR(VLOOKUP(E3,科目・教員!$A$1:$B$357,2,0),"") | G4: =IFERROR(VLOOKUP(G3,科目・教員!$A$1:$B$357,2,0),"") | I4: =IFERROR(VLOOKUP(I3,科目・教員!$A$1:$B$357,2,0),"") | K4: =IFERROR(VLOOKUP(K3,科目・教員!$A$1:$B$357,2,0),"") | M4: =IFERROR(VLOOKUP(M3,科目・教員!$A$1:$B$357,2,0),"") | O4: =IFERROR(VLOOKUP(O3,科目・教員!$A$1:$B$357,2,0),"") | Q4: =IFERROR(VLOOKUP(Q3,科目・教員!$A$1:$B$357,2,0),"") | S4: =IFERROR(VLOOKUP(S3,科目・教員!$A$1:$B$357,2,0),"")
B5: 使用教室 | C5: =VLOOKUP($C2,'2025年度(1年前期)'!$B$5:$N$208,COLUMN('2025年度(1年前期)'!$C$5)+1,0)&"" | E5: =VLOOKUP($C2,'2025年度(2年前期)'!$B$5:$N$208,COLUMN('2025年度(2年前期)'!$C$5)+1,0)&"" | G5: =VLOOKUP($C2,'2025年度(3年前期)'!$B$5:$N$208,COLUMN('2025年度(3年前期)'!$C$5)+1,0)&"" | I5: =VLOOKUP($C2,'2025年度(4年前期)'!$B$5:$N$208,COLUMN('2025年度(4年前期)'!$C$5)+1,0)&"" | K5: =VLOOKUP($C2,'2025年度(助産前期)'!$B$5:$N$208,COLUMN('2025年度(助産前期)'!$C$5)+1,0)&"" | M5: =VLOOKUP($C2,'2025年度(M1前期)'!$B$5:$N$208,COLUMN('2025年度(M1前期)'!C$5)+1,0)&"" | O5: =VLOOKUP($C2,'2025年度(M2前期)'!$B$5:$N$208,COLUMN('2025年度(M2前期)'!$C$5)+1,0)&"" | Q5: =VLOOKUP($C2,'2025年度(D1前期)'!$B$5:$N$208,COLUMN('2025年度(D1前期)'!$C$5)+1,0)&"" | S5: =VLOOKUP($C2,'2025年度(D23前期)'!$B$5:$N$208,COLUMN('2025年度(D23前期)'!$C$5)+1,0)&""
B6: 備 考
A7: ２時限（11：00～12：30） | B7: 科目名 | C7: =VLOOKUP($C2,'2025年度(1年前期)'!$B$5:$N$208,COLUMN('2025年度(1年前期)'!$E$5),0)&"" | E7: =VLOOKUP($C2,'2025年度(2年前期)'!$B$5:$N$208,COLUMN('2025年度(2年前期)'!$E$5),0)&"" | G7: =VLOOKUP($C2,'2025年度(3年前期)'!$B$5:$N$208,COLUMN('2025年度(3年前期)'!$E$5),0)&"" | I7: =VLOOKUP($C2,'2025年度(4年前期)'!$B$5:$N$208,COLUMN('2025年度(4年前期)'!$E$5),0)&"" | K7: =VLOOKUP($C2,'2025年度(助産前期)'!$B$5:$N$208,COLUMN('2025年度(助産前期)'!$E$5),0)&"" | M7: =VLOOKUP($C2,'2025年度(M1前期)'!$B$5:$N$208,COLUMN('2025年度(M1前期)'!$E$5),0)&"" | O7: =VLOOKUP($C2,'2025年度(M2前期)'!$B$5:$N$208,COLUMN('2025年度(M2前期)'!$E$5),0)&"" | Q7: =VLOOKUP($C2,'2025年度(D1前期)'!$B$5:$N$208,COLUMN('2025年度(D1前期)'!$E$5),0)&"" | S7: =VLOOKUP($C2,'2025年度(D23前期)'!$B$5:$N$208,COLUMN('2025年度(D23前期)'!$E$5),0)&"" | Z7: =A7 -> ２時限（11：00～12：30）
B8: 教 官 | C8: =IFERROR(VLOOKUP(C7,科目・教員!$A$1:$B$357,2,0),"") | E8: =IFERROR(VLOOKUP(E7,科目・教員!$A$1:$B$357,2,0),"") | G8: =IFERROR(VLOOKUP(G7,科目・教員!$A$1:$B$357,2,0),"") | I8: =IFERROR(VLOOKUP(I7,科目・教員!$A$1:$B$357,2,0),"") | K8: =IFERROR(VLOOKUP(K7,科目・教員!$A$1:$B$357,2,0),"") | M8: =IFERROR(VLOOKUP(M7,科目・教員!$A$1:$B$357,2,0),"") | O8: =IFERROR(VLOOKUP(O7,科目・教員!$A$1:$B$357,2,0),"") | Q8: =IFERROR(VLOOKUP(Q7,科目・教員!$A$1:$B$357,2,0),"") | S8: =IFERROR(VLOOKUP(S7,科目・教員!$A$1:$B$357,2,0),"")
B9: 使用教室 | C9: =VLOOKUP($C2,'2025年度(1年前期)'!$B$5:$N$208,COLUMN('2025年度(1年前期)'!$E$5)+1,0)&"" | E9: =VLOOKUP($C2,'2025年度(2年前期)'!$B$5:$N$208,COLUMN('2025年度(2年前期)'!$E$5)+1,0)&"" | G9: =VLOOKUP($C2,'2025年度(3年前期)'!$B$5:$N$208,COLUMN('2025年度(3年前期)'!$E$5)+1,0)&"" | I9: =VLOOKUP($C2,'2025年度(4年前期)'!$B$5:$N$208,COLUMN('2025年度(4年前期)'!$E$5)+1,0)&"" | K9: =VLOOKUP($C2,'2025年度(助産前期)'!$B$5:$N$208,COLUMN('2025年度(助産前期)'!$E$5)+1,0)&"" | M9: =VLOOKUP($C2,'2025年度(M1前期)'!$B$5:$N$208,COLUMN('2025年度(M1前期)'!$E$5)+1,0)&"" | O9: =VLOOKUP($C2,'2025年度(M2前期)'!$B$5:$N$208,COLUMN('2025年度(M2前期)'!$E$5)+1,0)&"" | Q9: =VLOOKUP($C2,'2025年度(D1前期)'!$B$5:$N$208,COLUMN('2025年度(D1前期)'!$E$5)+1,0)&"" | S9: =VLOOKUP($C2,'2025年度(D23前期)'!$B$5:$N$208,COLUMN('2025年度(D23前期)'!$E$5)+1,0)&""
B10: 備 考
A11: 昼休み（12：30～13：30） | B11: 活動名 | Z11: =A11 -> 昼休み（12：30～13：30）
B12: 責任者
B13: 使用教室
B14: 備 考
A15: ３時限（13：30～15：00） | B15: 科目名 | C15: =VLOOKUP($C2,'2025年度(1年前期)'!$B$5:$N$208,COLUMN('2025年度(1年前期)'!$G$5),0)&"" | E15: =VLOOKUP($C2,'2025年度(2年前期)'!$B$5:$N$208,COLUMN('2025年度(2年前期)'!$G$5),0)&"" | G15: =VLOOKUP($C2,'2025年度(3年前期)'!$B$5:$N$208,COLUMN('2025年度(3年前期)'!$G$5),0)&"" | I15: =VLOOKUP($C2,'2025年度(4年前期)'!$B$5:$N$208,COLUMN('2025年度(4年前期)'!$G$5),0)&"" | K15: =VLOOKUP($C2,'2025年度(助産前期)'!$B$5:$N$208,COLUMN('2025年度(助産前期)'!$G$5),0)&"" | M15: =VLOOKUP($C2,'2025年度(M1前期)'!$B$5:$N$208,COLUMN('2025年度(M1前期)'!$G$5),0)&"" | O15: =VLOOKUP($C2,'2025年度(M2前期)'!$B$5:$N$208,COLUMN('2025年度(M2前期)'!$G$5),0)&"" | Q15: =VLOOKUP($C2,'2025年度(D1前期)'!$B$5:$N$208,COLUMN('2025年度(D1前期)'!$G$5),0)&"" | S15: =VLOOKUP($C2,'2025年度(D23前期)'!$B$5:$N$208,COLUMN('2025年度(D23前期)'!$G$5),0)&"" | Z15: =A15 -> ３時限（13：30～15：00）
B16: 教 官 | C16: =IFERROR(VLOOKUP(C15,科目・教員!$A$1:$B$357,2,0),"") | E16: =IFERROR(VLOOKUP(E15,科目・教員!$A$1:$B$357,2,0),"") | G16: =IFERROR(VLOOKUP(G15,科目・教員!$A$1:$B$357,2,0),"") | I16: =IFERROR(VLOOKUP(I15,科目・教員!$A$1:$B$357,2,0),"") | K16: =IFERROR(VLOOKUP(K15,科目・教員!$A$1:$B$357,2,0),"") | M16: =IFERROR(VLOOKUP(M15,科目・教員!$A$1:$B$357,2,0),"") | O16: =IFERROR(VLOOKUP(O15,科目・教員!$A$1:$B$357,2,0),"") | Q16: =IFERROR(VLOOKUP(Q15,科目・教員!$A$1:$B$357,2,0),"") | S16: =IFERROR(VLOOKUP(S15,科目・教員!$A$1:$B$357,2,0),"")
B17: 使用教室 | C17: =VLOOKUP($C2,'2025年度(1年前期)'!$B$5:$N$208,COLUMN('2025年度(1年前期)'!$G$5)+1,0)&"" | E17: =VLOOKUP($C2,'2025年度(2年前期)'!$B$5:$N$208,COLUMN('2025年度(2年前期)'!$G$5)+1,0)&"" | G17: =VLOOKUP($C2,'2025年度(3年前期)'!$B$5:$N$208,COLUMN('2025年度(3年前期)'!$G$5)+1,0)&"" | I17: =VLOOKUP($C2,'2025年度(4年前期)'!$B$5:$N$208,COLUMN('2025年度(4年前期)'!$G$5)+1,0)&"" | K17: =VLOOKUP($C2,'2025年度(助産前期)'!$B$5:$N$208,COLUMN('2025年度(助産前期)'!$G$5)+1,0)&"" | M17: =VLOOKUP($C2,'2025年度(M1前期)'!$B$5:$N$208,COLUMN('2025年度(M1前期)'!$G$5)+1,0)&"" | O17: =VLOOKUP($C2,'2025年度(M2前期)'!$B$5:$N$208,COLUMN('2025年度(M2前期)'!$G$5)+1,0)&"" | Q17: =VLOOKUP($C2,'2025年度(D1前期)'!$B$5:$N$208,COLUMN('2025年度(D1前期)'!$G$5)+1,0)&"" | S17: =VLOOKUP($C2,'2025年度(D23前期)'!$B$5:$N$208,COLUMN('2025年度(D23前期)'!$G$5)+1,0)&""
B18: 備 考
A19: ４時限（15：10～16：40） | B19: 科目名 | C19: =VLOOKUP($C2,'2025年度(1年前期)'!$B$5:$N$208,COLUMN('2025年度(1年前期)'!$I$5),0)&"" | E19: =VLOOKUP($C2,'2025年度(2年前期)'!$B$5:$N$208,COLUMN('2025年度(2年前期)'!$I$5),0)&"" | G19: =VLOOKUP($C2,'2025年度(3年前期)'!$B$5:$N$208,COLUMN('2025年度(3年前期)'!$I$5),0)&"" | I19: =VLOOKUP($C2,'2025年度(4年前期)'!$B$5:$N$208,COLUMN('2025年度(4年前期)'!$I$5),0)&"" | K19: =VLOOKUP($C2,'2025年度(助産前期)'!$B$5:$N$208,COLUMN('2025年度(助産前期)'!$I$5),0)&"" | M19: =VLOOKUP($C2,'2025年度(M1前期)'!$B$5:$N$208,COLUMN('2025年度(M1前期)'!$I$5),0)&"" | O19: =VLOOKUP($C2,'2025年度(M2前期)'!$B$5:$N$208,COLUMN('2025年度(M2前期)'!$I$5),0)&"" | Q19: =VLOOKUP($C2,'2025年度(D1前期)'!$B$5:$N$208,COLUMN('2025年度(D1前期)'!$I$5),0)&"" | S19: =VLOOKUP($C2,'2025年度(D23前期)'!$B$5:$N$208,COLUMN('2025年度(D23前期)'!$I$5),0)&"" | Z19: =A19 -> ４時限（15：10～16：40）
B20: 教 官 | C20: =IFERROR(VLOOKUP(C19,科目・教員!$A$1:$B$357,2,0),"") | E20: =IFERROR(VLOOKUP(E19,科目・教員!$A$1:$B$357,2,0),"") | G20: =IFERROR(VLOOKUP(G19,科目・教員!$A$1:$B$357,2,0),"") | I20: =IFERROR(VLOOKUP(I19,科目・教員!$A$1:$B$357,2,0),"") | K20: =IFERROR(VLOOKUP(K19,科目・教員!$A$1:$B$357,2,0),"") | M20: =IFERROR(VLOOKUP(M19,科目・教員!$A$1:$B$357,2,0),"") | O20: =IFERROR(VLOOKUP(O19,科目・教員!$A$1:$B$357,2,0),"") | Q20: =IFERROR(VLOOKUP(Q19,科目・教員!$A$1:$B$357,2,0),"") | S20: =IFERROR(VLOOKUP(S19,科目・教員!$A$1:$B$357,2,0),"")
B21: 使用教室 | C21: =VLOOKUP($C2,'2025年度(1年前期)'!$B$5:$N$208,COLUMN('2025年度(1年前期)'!$I$5)+1,0)&"" | E21: =VLOOKUP($C2,'2025年度(2年前期)'!$B$5:$N$208,COLUMN('2025年度(2年前期)'!$I$5)+1,0)&"" | G21: =VLOOKUP($C2,'2025年度(3年前期)'!$B$5:$N$208,COLUMN('2025年度(3年前期)'!$I$5)+1,0)&"" | I21: =VLOOKUP($C2,'2025年度(4年前期)'!$B$5:$N$208,COLUMN('2025年度(4年前期)'!$I$5)+1,0)&"" | K21: =VLOOKUP($C2,'2025年度(助産前期)'!$B$5:$N$208,COLUMN('2025年度(助産前期)'!$I$5)+1,0)&"" | M21: =VLOOKUP($C2,'2025年度(M1前期)'!$B$5:$N$208,COLUMN('2025年度(M1前期)'!$I$5)+1,0)&"" | O21: =VLOOKUP($C2,'2025年度(M2前期)'!$B$5:$N$208,COLUMN('2025年度(M2前期)'!$I$5)+1,0)&"" | Q21: =VLOOKUP($C2,'2025年度(D1前期)'!$B$5:$N$208,COLUMN('2025年度(D1前期)'!$I$5)+1,0)&"" | S21: =VLOOKUP($C2,'2025年度(D23前期)'!$B$5:$N$208,COLUMN('2025年度(D23前期)'!$I$5)+1,0)&""
B22: 備 考
A23: ５時限（16：50～18：20） | B23: 科目名 | C23: =VLOOKUP($C2,'2025年度(1年前期)'!$B$5:$N$208,COLUMN('2025年度(1年前期)'!$K$5),0)&"" | E23: =VLOOKUP($C2,'2025年度(2年前期)'!$B$5:$N$208,COLUMN('2025年度(2年前期)'!$K$5),0)&"" | G23: =VLOOKUP($C2,'2025年度(3年前期)'!$B$5:$N$208,COLUMN('2025年度(3年前期)'!$K$5),0)&"" | I23: =VLOOKUP($C2,'2025年度(4年前期)'!$B$5:$N$208,COLUMN('2025年度(4年前期)'!$K$5),0)&"" | K23: =VLOOKUP($C2,'2025年度(助産前期)'!$B$5:$N$208,COLUMN('2025年度(助産前期)'!$K$5),0)&"" | M23: =VLOOKUP($C2,'2025年度(M1前期)'!$B$5:$N$208,COLUMN('2025年度(M1前期)'!$K$5),0)&"" | O23: =VLOOKUP($C2,'2025年度(M2前期)'!$B$5:$N$208,COLUMN('2025年度(M2前期)'!$K$5),0)&"" | Q23: =VLOOKUP($C2,'2025年度(D1前期)'!$B$5:$N$208,COLUMN('2025年度(D1前期)'!$K$5),0)&"" | S23: =VLOOKUP($C2,'2025年度(D23前期)'!$B$5:$N$208,COLUMN('2025年度(D23前期)'!$K$5),0)&"" | Z23: =A23 -> ５時限（16：50～18：20）
B24: 教 官 | C24: =IFERROR(VLOOKUP(C23,科目・教員!$A$1:$B$357,2,0),"") | E24: =IFERROR(VLOOKUP(E23,科目・教員!$A$1:$B$357,2,0),"") | G24: =IFERROR(VLOOKUP(G23,科目・教員!$A$1:$B$357,2,0),"") | I24: =IFERROR(VLOOKUP(I23,科目・教員!$A$1:$B$357,2,0),"") | K24: =IFERROR(VLOOKUP(K23,科目・教員!$A$1:$B$357,2,0),"") | M24: =IFERROR(VLOOKUP(M23,科目・教員!$A$1:$B$357,2,0),"") | O24: =IFERROR(VLOOKUP(O23,科目・教員!$A$1:$B$357,2,0),"") | Q24: =IFERROR(VLOOKUP(Q23,科目・教員!$A$1:$B$357,2,0),"") | S24: =IFERROR(VLOOKUP(S23,科目・教員!$A$1:$B$357,2,0),"")
B25: 使用教室 | C25: =VLOOKUP($C2,'2025年度(1年前期)'!$B$5:$N$208,COLUMN('2025年度(1年前期)'!$K$5)+1,0)&"" | E25: =VLOOKUP($C2,'2025年度(2年前期)'!$B$5:$N$208,COLUMN('2025年度(2年前期)'!$K$5)+1,0)&"" | G25: =VLOOKUP($C2,'2025年度(3年前期)'!$B$5:$N$208,COLUMN('2025年度(3年前期)'!$K$5)+1,0)&"" | I25: =VLOOKUP($C2,'2025年度(4年前期)'!$B$5:$N$208,COLUMN('2025年度(4年前期)'!$K$5)+1,0)&"" | K25: =VLOOKUP($C2,'2025年度(助産前期)'!$B$5:$N$208,COLUMN('2025年度(助産前期)'!$K$5)+1,0)&"" | M25: =VLOOKUP($C2,'2025年度(M1前期)'!$B$5:$N$208,COLUMN('2025年度(M1前期)'!$K$5)+1,0)&"" | O25: =VLOOKUP($C2,'2025年度(M2前期)'!$B$5:$N$208,COLUMN('2025年度(M2前期)'!$K$5)+1,0)&"" | Q25: =VLOOKUP($C2,'2025年度(D1前期)'!$B$5:$N$208,COLUMN('2025年度(D1前期)'!$K$5)+1,0)&"" | S25: =VLOOKUP($C2,'2025年度(D23前期)'!$B$5:$N$208,COLUMN('2025年度(D23前期)'!$K$5)+1,0)&""
B26: 備 考
C27: =C2+1 -> 45810 | U27: =C27 -> 45810 | AA27: 101 | AB27: 102 | AC27: 103 | AD27: 在宅実習室 | AE27: 成人実習室 | AF27: 講堂 | AG27: 201 | AH27: 202 | AI27: 203 | AJ27: 204 | AK27: 205 | AL27: 基礎実習室 | AM27: 母性・小児実習室 | AN27: 演習21 | AO27: 演習22 | AP27: 演習23 | AQ27: 演習24 | AR27: 演習25 | AS27: 演習26 | AT27: 演習27 | AU27: 演習28 | AV27: 演習29 | AW27: 301 | AX27: 302 | AY27: 303 | AZ27: 304 | BA27: 臨床１ | BB27: 臨床２ | BC27: LL1 | BD27: LL2 | BE27: 実験室 | BF27: 情報処理室 | BG27: 演習31 | BH27: 演習32 | BI27: セミナー室1 | BJ27: セミナー室2 | BK27: セミナー室3 | BL27: セミナー室4 | BM27: セミナー室5 | BN27: 大講義室 | BO27: アリーナ | BP27: 多目的ルーム | BQ27: 研修１ | BR27: 研修３ | BS27: 研修４ | BT27: 研修５ | BU27: 研修６ | BV27: 研修７ | BW27: 視聴覚室
A28: １時限（09：20～10：50） | B28: 科目名 | C28: =VLOOKUP($C27,'2025年度(1年前期)'!$B$5:$N$208,COLUMN('2025年度(1年前期)'!$C$5),0)&"" -> 生活援助論Ⅰ (ABCD:環境整備、1･2年生合同) | E28: =VLOOKUP($C27,'2025年度(2年前期)'!$B$5:$N$208,COLUMN('2025年度(2年前期)'!$C$5),0)&"" -> 生活援助論Ⅲ (ABCD:環境整備、1･2年生合同) | G28: =VLOOKUP($C27,'2025年度(3年前期)'!$B$5:$N$208,COLUMN('2025年度(3年前期)'!$C$5),0)&"" -> 看護実践と研究成果の活用 | I28: =VLOOKUP($C27,'2025年度(4年前期)'!$B$5:$N$208,COLUMN('2025年度(4年前期)'!$C$5),0)&"" -> 看護学統合 演習・実習 | K28: =VLOOKUP($C27,'2025年度(助産前期)'!$B$5:$N$208,COLUMN('2025年度(助産前期)'!$C$5),0)&"" | M28: =VLOOKUP($C27,'2025年度(M1前期)'!$B$5:$N$208,COLUMN('2025年度(M1前期)'!$C$5),0)&"" -> 看護情報・管理学特論Ａ－Ⅰ 看護管理学 | O28: =VLOOKUP($C27,'2025年度(M2前期)'!$B$5:$N$208,COLUMN('2025年度(M2前期)'!$C$5),0)&"" -> 成育看護学演習Ａ－Ⅲ(小児) 成人看護学演習Ａ－Ⅱ 成育看護学演習Ａ－Ⅲ(母性) | Q28: =VLOOKUP($C27,'2025年度(D1前期)'!$B$5:$N$208,COLUMN('2025年度(D1前期)'!$C$5),0)&"" | S28: =VLOOKUP($C27,'2025年度(D23前期)'!$B$5:$N$208,COLUMN('2025年度(D23前期)'!$C$5),0)&"" -> 特別研究 | U28: 1～4限 | V28: 1～5限 | W28: 9時～18時 | Y28: 1～4限 | Z28: =A28 -> １時限（09：20～10：50） | AE28: 生活援助論Ⅰ･Ⅲ | AG28: 生活援助論Ⅰ･Ⅲ | AH28: 生活援助論Ⅰ･Ⅲ | AL28: 生活援助論Ⅰ･Ⅲ | AN28: 修学支援 | AX28: 統合演習（成育） | BA28: 看護情報･管理学特論A-Ⅰ/看護管理学 | BB28: 統合演習(長寿) | BN28: 看護実践と研究成果の活用
B29: 教 官 | C29: =IFERROR(VLOOKUP(C28,科目・教員!$A$1:$B$357,2,0),"") | E29: =IFERROR(VLOOKUP(E28,科目・教員!$A$1:$B$357,2,0),"") | G29: =IFERROR(VLOOKUP(G28,科目・教員!$A$1:$B$357,2,0),"") -> 西岡 みどり | I29: =IFERROR(VLOOKUP(I28,科目・教員!$A$1:$B$357,2,0),"") | K29: =IFERROR(VLOOKUP(K28,科目・教員!$A$1:$B$357,2,0),"") | M29: =IFERROR(VLOOKUP(M28,科目・教員!$A$1:$B$357,2,0),"") | O29: =IFERROR(VLOOKUP(O28,科目・教員!$A$1:$B$357,2,0),"") | Q29: =IFERROR(VLOOKUP(Q28,科目・教員!$A$1:$B$357,2,0),"") | S29: =IFERROR(VLOOKUP(S28,科目・教員!$A$1:$B$357,2,0),"") | U29: 統合演習（成育） | V29: 統合演習(長寿) | W29: フィジカルアセスメント | Y29: 修学支援
B30: 使用教室 | C30: =VLOOKUP($C27,'2025年度(1年前期)'!$B$5:$N$208,COLUMN('2025年度(1年前期)'!$C$5)+1,0)&"" -> 201･202･基礎実･成人実 | E30: =VLOOKUP($C27,'2025年度(2年前期)'!$B$5:$N$208,COLUMN('2025年度(2年前期)'!$C$5)+1,0)&"" -> 201･202･基礎実･成人実 | G30: =VLOOKUP($C27,'2025年度(3年前期)'!$B$5:$N$208,COLUMN('2025年度(3年前期)'!$C$5)+1,0)&"" -> 大講義室 | I30: =VLOOKUP($C27,'2025年度(4年前期)'!$B$5:$N$208,COLUMN('2025年度(4年前期)'!$C$5)+1,0)&"" -> 成育：302 長寿:臨床2 | K30: =VLOOKUP($C27,'2025年度(助産前期)'!$B$5:$N$208,COLUMN('2025年度(助産前期)'!$C$5)+1,0)&"" | M30: =VLOOKUP($C27,'2025年度(M1前期)'!$B$5:$N$208,COLUMN('2025年度(M1前期)'!C$5)+1,0)&"" -> 臨床講義室1(合同) | O30: =VLOOKUP($C27,'2025年度(M2前期)'!$B$5:$N$208,COLUMN('2025年度(M2前期)'!$C$5)+1,0)&"" -> 成育:別途指定 成人:別途指定 | Q30: =VLOOKUP($C27,'2025年度(D1前期)'!$B$5:$N$208,COLUMN('2025年度(D1前期)'!$C$5)+1,0)&"" | S30: =VLOOKUP($C27,'2025年度(D23前期)'!$B$5:$N$208,COLUMN('2025年度(D23前期)'!$C$5)+1,0)&"" | U30: 野村先生 | V30: 臨床講義室2 | W30: 自主練 | Y30: 演習21
B31: 備 考 | U31: 302教室 | V31: 松岡先生 | W31: 長岡先生 | Y31: 教務係
A32: ２時限（11：00～12：30） | B32: 科目名 | C32: =VLOOKUP($C27,'2025年度(1年前期)'!$B$5:$N$208,COLUMN('2025年度(1年前期)'!$E$5),0)&"" -> 生活援助論Ⅰ (ABCD) | E32: =VLOOKUP($C27,'2025年度(2年前期)'!$B$5:$N$208,COLUMN('2025年度(2年前期)'!$E$5),0)&"" -> 疾病･病態論Ⅱ (加藤先生) | G32: =VLOOKUP($C27,'2025年度(3年前期)'!$B$5:$N$208,COLUMN('2025年度(3年前期)'!$E$5),0)&"" -> 看護実践と研究成果の活用 | I32: =VLOOKUP($C27,'2025年度(4年前期)'!$B$5:$N$208,COLUMN('2025年度(4年前期)'!$E$5),0)&"" -> 看護学統合 演習・実習 | K32: =VLOOKUP($C27,'2025年度(助産前期)'!$B$5:$N$208,COLUMN('2025年度(助産前期)'!$E$5),0)&"" | M32: =VLOOKUP($C27,'2025年度(M1前期)'!$B$5:$N$208,COLUMN('2025年度(M1前期)'!$E$5),0)&"" -> 看護情報・管理学特論Ａ－Ⅰ 看護管理学 | O32: =VLOOKUP($C27,'2025年度(M2前期)'!$B$5:$N$208,COLUMN('2025年度(M2前期)'!$E$5),0)&"" -> 成育看護学演習Ａ－Ⅲ(小児) 成人看護学演習Ａ－Ⅱ 成育看護学演習Ａ－Ⅲ(母性) | Q32: =VLOOKUP($C27,'2025年度(D1前期)'!$B$5:$N$208,COLUMN('2025年度(D1前期)'!$E$5),0)&"" | S32: =VLOOKUP($C27,'2025年度(D23前期)'!$B$5:$N$208,COLUMN('2025年度(D23前期)'!$E$5),0)&"" -> 特別研究 | W32: 成人実習室 | Z32: =A32 -> ２時限（11：00～12：30） | AA32: 疾病･病態論Ⅱ | AE32: 生活援助論Ⅰ | AG32: 生活援助論Ⅰ | AH32: 生活援助論Ⅰ | AL32: 生活援助論Ⅰ | AN32: 修学支援 | AX32: 統合演習（成育） | BA32: 看護情報･管理学特論A-Ⅰ/看護管理学 | BB32: 統合演習(長寿) | BN32: 看護実践と研究成果の活用
B33: 教 官 | C33: =IFERROR(VLOOKUP(C32,科目・教員!$A$1:$B$357,2,0),"") | E33: =IFERROR(VLOOKUP(E32,科目・教員!$A$1:$B$357,2,0),"") | G33: =IFERROR(VLOOKUP(G32,科目・教員!$A$1:$B$357,2,0),"") -> 西岡 みどり | I33: =IFERROR(VLOOKUP(I32,科目・教員!$A$1:$B$357,2,0),"") | K33: =IFERROR(VLOOKUP(K32,科目・教員!$A$1:$B$357,2,0),"") | M33: =IFERROR(VLOOKUP(M32,科目・教員!$A$1:$B$357,2,0),"") | O33: =IFERROR(VLOOKUP(O32,科目・教員!$A$1:$B$357,2,0),"") | Q33: =IFERROR(VLOOKUP(Q32,科目・教員!$A$1:$B$357,2,0),"") | S33: =IFERROR(VLOOKUP(S32,科目・教員!$A$1:$B$357,2,0),"")
B34: 使用教室 | C34: =VLOOKUP($C27,'2025年度(1年前期)'!$B$5:$N$208,COLUMN('2025年度(1年前期)'!$E$5)+1,0)&"" -> 201･202･基礎実･成人実 | E34: =VLOOKUP($C27,'2025年度(2年前期)'!$B$5:$N$208,COLUMN('2025年度(2年前期)'!$E$5)+1,0)&"" -> リアルタイム (101) | G34: =VLOOKUP($C27,'2025年度(3年前期)'!$B$5:$N$208,COLUMN('2025年度(3年前期)'!$E$5)+1,0)&"" -> 大講義室 | I34: =VLOOKUP($C27,'2025年度(4年前期)'!$B$5:$N$208,COLUMN('2025年度(4年前期)'!$E$5)+1,0)&"" -> 成育：302 長寿:臨床2 | K34: =VLOOKUP($C27,'2025年度(助産前期)'!$B$5:$N$208,COLUMN('2025年度(助産前期)'!$E$5)+1,0)&"" | M34: =VLOOKUP($C27,'2025年度(M1前期)'!$B$5:$N$208,COLUMN('2025年度(M1前期)'!$E$5)+1,0)&"" -> 臨床講義室1(合同) | O34: =VLOOKUP($C27,'2025年度(M2前期)'!$B$5:$N$208,COLUMN('2025年度(M2前期)'!$E$5)+1,0)&"" -> 成育:別途指定 成人:別途指定 | Q34: =VLOOKUP($C27,'2025年度(D1前期)'!$B$5:$N$208,COLUMN('2025年度(D1前期)'!$E$5)+1,0)&"" | S34: =VLOOKUP($C27,'2025年度(D23前期)'!$B$5:$N$208,COLUMN('2025年度(D23前期)'!$E$5)+1,0)&""
B35: 備 考
A36: 昼休み（12：30～13：30） | B36: 活動名 | Z36: =A36 -> 昼休み（12：30～13：30） | AN36: 修学支援 | AX36: 統合演習（成育） | BB36: 統合演習(長寿)
B37: 責任者
B38: 使用教室
B39: 備 考
A40: ３時限（13：30～15：00） | B40: 科目名 | C40: =VLOOKUP($C27,'2025年度(1年前期)'!$B$5:$N$208,COLUMN('2025年度(1年前期)'!$G$5),0)&"" -> B型肝炎① 14:00～15:00 (Bグループは早めに受ける) | E40: =VLOOKUP($C27,'2025年度(2年前期)'!$B$5:$N$208,COLUMN('2025年度(2年前期)'!$G$5),0)&"" -> フィジカルアセスメント | G40: =VLOOKUP($C27,'2025年度(3年前期)'!$B$5:$N$208,COLUMN('2025年度(3年前期)'!$G$5),0)&"" -> 地域･在宅看護学実践論 | I40: =VLOOKUP($C27,'2025年度(4年前期)'!$B$5:$N$208,COLUMN('2025年度(4年前期)'!$G$5),0)&"" -> 看護学統合 演習・実習(N95マスクフィットテスト) | K40: =VLOOKUP($C27,'2025年度(助産前期)'!$B$5:$N$208,COLUMN('2025年度(助産前期)'!$G$5),0)&"" | M40: =VLOOKUP($C27,'2025年度(M1前期)'!$B$5:$N$208,COLUMN('2025年度(M1前期)'!$G$5),0)&"" | O40: =VLOOKUP($C27,'2025年度(M2前期)'!$B$5:$N$208,COLUMN('2025年度(M2前期)'!$G$5),0)&"" -> 特別研究 | Q40: =VLOOKUP($C27,'2025年度(D1前期)'!$B$5:$N$208,COLUMN('2025年度(D1前期)'!$G$5),0)&"" -> 国際看護学特論Ｂ | S40: =VLOOKUP($C27,'2025年度(D23前期)'!$B$5:$N$208,COLUMN('2025年度(D23前期)'!$G$5),0)&"" -> 特別研究 | Z40: =A40 -> ３時限（13：30～15：00） | AA40: N95マスクフィットテスト | AE40: N95マスクフィットテスト | AH40: フィジカルアセスメント | AI40: フィジカルアセスメント | AL40: フィジカルアセスメント | AN40: 修学支援 | AX40: 統合演習（成育） | BB40: 統合演習(長寿) | BN40: 地域･在宅看護学実践論
...

Sheet 2025年7月
A1: 45839 | C1: １年 | E1: ２年 | G1: ３年 | I1: ４年 | K1: 助産 | M1: 研究課程部 Ｍ１ | O1: 研究課程部 Ｍ２ | Q1: 研究課程部 Ｄ１ | S1: 研究課程部 Ｄ２３ | U1: =A1 -> 45839 | V1: 授業外その他教室等管理スケジュール | AA1: １階 | AG1: ２階 | AW1: ３階 | BI1: ４階 | BN1: 体育棟 | BP1: 福利棟 | BQ1: 研修棟
C2: =A1 -> 45839 | U2: =C2 -> 45839 | AA2: 101 | AB2: 102 | AC2: 103 | AD2: 在宅実習室 | AE2: 成人実習室 | AF2: 講堂 | AG2: 201 | AH2: 202 | AI2: 203 | AJ2: 204 | AK2: 205 | AL2: 基礎実習室 | AM2: 母性・小児実習室 | AN2: 演習21 | AO2: 演習22 | AP2: 演習23 | AQ2: 演習24 | AR2: 演習25 | AS2: 演習26 | AT2: 演習27 | AU2: 演習28 | AV2: 演習29 | AW2: 301 | AX2: 302 | AY2: 303 | AZ2: 304 | BA2: 臨床１ | BB2: 臨床２ | BC2: LL1 | BD2: LL2 | BE2: 実験室 | BF2: 情報処理室 | BG2: 演習31 | BH2: 演習32 | BI2: セミナー室１ | BJ2: セミナー室２ | BK2: セミナー室3 | BL2: セミナー室4 | BM2: セミナー室5 | BN2: 大講義室 | BO2: アリーナ | BP2: 多目的ルーム | BQ2: 研修１ | BR2: 研修３ | BS2: 研修４ | BT2: 研修５ | BU2: 研修６ | BV2: 研修７ | BW2: 視聴覚室
A3: １時限（09：20～10：50） | B3: 科目名 | C3: =VLOOKUP($C2,'2025年度(1年前期)'!$B$5:$N$208,COLUMN('2025年度(1年前期)'!$C$5),0)&"" -> 人体の構造と機能Ⅱ | E3: =VLOOKUP($C2,'2025年度(2年前期)'!$B$5:$N$208,COLUMN('2025年度(2年前期)'!$C$5),0)&"" | G3: =VLOOKUP($C2,'2025年度(3年前期)'!$B$5:$N$208,COLUMN('2025年度(3年前期)'!$C$5),0)&"" -> 周産期看護 | I3: =VLOOKUP($C2,'2025年度(4年前期)'!$B$5:$N$208,COLUMN('2025年度(4年前期)'!$C$5),0)&"" -> 政策医療看護学実習 | K3: =VLOOKUP($C2,'2025年度(助産前期)'!$B$5:$N$208,COLUMN('2025年度(助産前期)'!$C$5),0)&"" -> 助産学臨床講義 | M3: =VLOOKUP($C2,'2025年度(M1前期)'!$B$5:$N$208,COLUMN('2025年度(M1前期)'!$C$5),0)&"" | O3: =VLOOKUP($C2,'2025年度(M2前期)'!$B$5:$N$208,COLUMN('2025年度(M2前期)'!$C$5),0)&"" | Q3: =VLOOKUP($C2,'2025年度(D1前期)'!$B$5:$N$208,COLUMN('2025年度(D1前期)'!$C$5),0)&"" -> 成育看護学特論Ｂ 成人看護学演習Ｂ | S3: =VLOOKUP($C2,'2025年度(D23前期)'!$B$5:$N$208,COLUMN('2025年度(D23前期)'!$C$5),0)&"" -> 特別研究 | Y3: 終日 | Z3: =A3 -> １時限（09：20～10：50） | AA3: 人体の構造と機能Ⅰ | AE3: 成人看護援助論Ⅲ・フィジカルアセスメント 自主練(授業優先) | AW3: 周産期看護
B4: 教 官 | C4: =IFERROR(VLOOKUP(C3,科目・教員!$A$1:$B$357,2,0),"") -> 本間 典子 | E4: =IFERROR(VLOOKUP(E3,科目・教員!$A$1:$B$357,2,0),"") | G4: =IFERROR(VLOOKUP(G3,科目・教員!$A$1:$B$357,2,0),"") -> 日置 智華子 | I4: =IFERROR(VLOOKUP(I3,科目・教員!$A$1:$B$357,2,0),"") -> 各担当教員 | K4: =IFERROR(VLOOKUP(K3,科目・教員!$A$1:$B$357,2,0),"") | M4: =IFERROR(VLOOKUP(M3,科目・教員!$A$1:$B$357,2,0),"") | O4: =IFERROR(VLOOKUP(O3,科目・教員!$A$1:$B$357,2,0),"") | Q4: =IFERROR(VLOOKUP(Q3,科目・教員!$A$1:$B$357,2,0),"") | S4: =IFERROR(VLOOKUP(S3,科目・教員!$A$1:$B$357,2,0),"") | Y4: 成人看護援助論Ⅲ
B5: 使用教室 | C5: =VLOOKUP($C2,'2025年度(1年前期)'!$B$5:$N$208,COLUMN('2025年度(1年前期)'!$C$5)+1,0)&"" -> 101 | E5: =VLOOKUP($C2,'2025年度(2年前期)'!$B$5:$N$208,COLUMN('2025年度(2年前期)'!$C$5)+1,0)&"" | G5: =VLOOKUP($C2,'2025年度(3年前期)'!$B$5:$N$208,COLUMN('2025年度(3年前期)'!$C$5)+1,0)&"" -> 301 | I5: =VLOOKUP($C2,'2025年度(4年前期)'!$B$5:$N$208,COLUMN('2025年度(4年前期)'!$C$5)+1,0)&"" | K5: =VLOOKUP($C2,'2025年度(助産前期)'!$B$5:$N$208,COLUMN('2025年度(助産前期)'!$C$5)+1,0)&"" | M5: =VLOOKUP($C2,'2025年度(M1前期)'!$B$5:$N$208,COLUMN('2025年度(M1前期)'!C$5)+1,0)&"" | O5: =VLOOKUP($C2,'2025年度(M2前期)'!$B$5:$N$208,COLUMN('2025年度(M2前期)'!$C$5)+1,0)&"" | Q5: =VLOOKUP($C2,'2025年度(D1前期)'!$B$5:$N$208,COLUMN('2025年度(D1前期)'!$C$5)+1,0)&"" -> 成育:別途指定 成人:別途指定 | S5: =VLOOKUP($C2,'2025年度(D23前期)'!$B$5:$N$208,COLUMN('2025年度(D23前期)'!$C$5)+1,0)&"" | Y5: フィジカルアセスメント
B6: 備 考 | Y6: 自主練
A7: ２時限（11：00～12：30） | B7: 科目名 | C7: =VLOOKUP($C2,'2025年度(1年前期)'!$B$5:$N$208,COLUMN('2025年度(1年前期)'!$E$5),0)&"" -> 基礎看護学実習Ⅰ オリエンテーション① | E7: =VLOOKUP($C2,'2025年度(2年前期)'!$B$5:$N$208,COLUMN('2025年度(2年前期)'!$E$5),0)&"" -> 疾病･病態論Ⅱ (望月先生②) | G7: =VLOOKUP($C2,'2025年度(3年前期)'!$B$5:$N$208,COLUMN('2025年度(3年前期)'!$E$5),0)&"" -> 国際看護論 | I7: =VLOOKUP($C2,'2025年度(4年前期)'!$B$5:$N$208,COLUMN('2025年度(4年前期)'!$E$5),0)&"" -> 政策医療看護学実習 | K7: =VLOOKUP($C2,'2025年度(助産前期)'!$B$5:$N$208,COLUMN('2025年度(助産前期)'!$E$5),0)&"" -> 助産学臨床講義 | M7: =VLOOKUP($C2,'2025年度(M1前期)'!$B$5:$N$208,COLUMN('2025年度(M1前期)'!$E$5),0)&"" -> 生理学特論 | O7: =VLOOKUP($C2,'2025年度(M2前期)'!$B$5:$N$208,COLUMN('2025年度(M2前期)'!$E$5),0)&"" | Q7: =VLOOKUP($C2,'2025年度(D1前期)'!$B$5:$N$208,COLUMN('2025年度(D1前期)'!$E$5),0)&"" -> 成育看護学特論Ｂ 成人看護学演習Ｂ | S7: =VLOOKUP($C2,'2025年度(D23前期)'!$B$5:$N$208,COLUMN('2025年度(D23前期)'!$E$5),0)&"" -> 特別研究 | Z7: =A7 -> ２時限（11：00～12：30） | AA7: 基礎看護学実習Ⅰオリエンテーション | AE7: 成人看護援助論Ⅲ・フィジカルアセスメント 自主練(授業優先) | AG7: 疾病･病態論Ⅱ | AW7: 国際看護論
